Workbook

Sheet Báo cáo
B3: Mã hàng | C3: Tên hàng | D3: ĐVT | E3: Đầu kỳ | F3: Nhập kho | G3: Xuất kho | H3: Cuối kỳ
E4: Số lượng | F4: Số lượng | G4: Số lượng | H4: Số lượng
A5: Tên kho : 02-Kho Văn phòng Công ty (20 ) | J5: Note:
B6: ĐH015 | C6: Đồng hồ D15 | D6: Cái | F6: ='Nhập Kho'!Q6 -> 2240 | G6: ='Xuất kho theo tháng'!CL6 -> 1740 | H6: =(E6+F6)-G6 -> 500
B7: ĐH015(SC) | C7: Đồng hồ sửa chữa 015 | D7: Cái | F7: ='Nhập Kho'!Q7 -> 6490 | G7: ='Xuất kho theo tháng'!CL7 -> 6490 | H7: =(E7+F7)-G7 -> 0
B8: ĐH015(SC) | C8: Đồng hồ sửa chữa 015 đơn vị | D8: Cái | F8: ='Nhập Kho'!Q8 -> 0 | G8: ='Xuất kho theo tháng'!CL8 -> 0 | H8: =(E8+F8)-G8 -> 0
B9: ĐH015-TAC | C9: Đồng hồ Thái Aichi MAM-15 ( không kèm rắc co) | D9: Cái | F9: ='Nhập Kho'!Q9 -> 0 | G9: ='Xuất kho theo tháng'!CL9 -> 0 | H9: =(E9+F9)-G9 -> 0
B10: ĐH025 | C10: Đồng hồ D25 | D10: Cái | F10: ='Nhập Kho'!Q11 -> 0 | G10: ='Xuất kho theo tháng'!CL11 -> 0 | H10: =(E10+F10)-G10 -> 0
B11: ĐH025(SC) | C11: Đồng hồ D25 (sửa chữa) | D11: Cái | F11: ='Nhập Kho'!Q12 -> 0 | G11: ='Xuất kho theo tháng'!CL12 -> 0 | H11: =(E11+F11)-G11 -> 0
B12: ĐH032 | C12: Đồng hồ D32 | D12: Cái | F12: ='Nhập Kho'!Q13 -> 0 | G12: ='Xuất kho theo tháng'!CL13 -> 0 | H12: =(E12+F12)-G12 -> 0
B13: ĐH032(SC) | C13: Đồng hồ D32 (sửa chữa) | D13: Cái | F13: ='Nhập Kho'!Q14 -> 0 | G13: ='Xuất kho theo tháng'!CL14 -> 0 | H13: =(E13+F13)-G13 -> 0
B14: ĐH040 | C14: Đồng hồ D40 | D14: Cái | F14: ='Nhập Kho'!Q15 -> 35 | G14: ='Xuất kho theo tháng'!CL15 -> 31 | H14: =(E14+F14)-G14 -> 4
B15: ĐH040(SC) | C15: Đồng hồ D40 (sửa chữa) | D15: Cái | F15: ='Nhập Kho'!Q16 -> 3 | G15: ='Xuất kho theo tháng'!CL16 -> 3 | H15: =(E15+F15)-G15 -> 0
B16: ĐH040-ĐLL | C16: Đồng hồ đo lưu lượng Turbobar hiệu Bermad DN40 | D16: Bộ | F16: ='Nhập Kho'!Q17 -> 1 | G16: ='Xuất kho theo tháng'!CL17 -> 0 | H16: =(E16+F16)-G16 -> 1
B17: ĐH050 | C17: Đồng hồ D50 | D17: Cái | F17: ='Nhập Kho'!Q18 -> 4 | G17: ='Xuất kho theo tháng'!CL18 -> 2 | H17: =(E17+F17)-G17 -> 2
B18: ĐH050(SC) | C18: Đồng hồ D50 (sửa chữa) | D18: Cái | F18: ='Nhập Kho'!Q19 -> 0 | G18: ='Xuất kho theo tháng'!CL19 -> 0 | H18: =(E18+F18)-G18 -> 0
B19: ĐH050-BM | C19: Đồng hồ DN50 hiệu Bermad | D19: Cái | F19: ='Nhập Kho'!Q20 -> 6 | G19: ='Xuất kho theo tháng'!CL20 -> 0 | H19: =(E19+F19)-G19 -> 6
B20: ĐH065 | C20: Đồng hồ D65 | D20: Cái | F20: ='Nhập Kho'!Q21 -> 5 | G20: ='Xuất kho theo tháng'!CL21 -> 1 | H20: =(E20+F20)-G20 -> 4 | I20: còn 2 treo kho 2
B21: ĐH065-ĐLL | C21: Đồng hồ đo lưu lượng Turbobar hiệu Bermad DN65 | D21: Bộ | F21: ='Nhập Kho'!Q22 -> 0 | G21: ='Xuất kho theo tháng'!CL22 -> 0 | H21: =(E21+F21)-G21 -> 0
B22: ĐH080 | C22: Đồng hồ D80 | D22: Cái | F22: ='Nhập Kho'!Q23 -> 4 | G22: ='Xuất kho theo tháng'!CL23 -> 2 | H22: =(E22+F22)-G22 -> 2
B23: ĐH100 | C23: Đồng hồ D100 | D23: Cái | F23: ='Nhập Kho'!Q24 -> 7 | G23: ='Xuất kho theo tháng'!CL24 -> 3 | H23: =(E23+F23)-G23 -> 4 | I23: còn 1 treo kho 3
B24: ĐH150 | C24: Đồng hồ D150 | D24: Cái | F24: ='Nhập Kho'!Q25 -> 4 | G24: ='Xuất kho theo tháng'!CL25 -> 1 | H24: =(E24+F24)-G24 -> 3
B25: ĐH150-CTOR | C25: Đồng hồ nước DN150 CONTOR-Metcon Qn=150m3/h, cấp B (Pvđ: 4,5-300m3/h) sửa chữa | D25: Cái | F25: ='Nhập Kho'!Q26 -> 1 | G25: ='Xuất kho theo tháng'!CL26 -> 0 | H25: =(E25+F25)-G25 -> 1 | I25: ĐÃ HỎNG
B26: ĐH200 | C26: Đồng hồ D200 | D26: Cái | F26: ='Nhập Kho'!Q27 -> 2 | G26: ='Xuất kho theo tháng'!CL27 -> 2 | H26: =(E26+F26)-G26 -> 0
B27: ĐH15 | C27: Đồng hồ D15 metcon | D27: Cái | F27: ='Nhập Kho'!Q28 -> 0 | H27: =(E27+F27)-G27 -> 0
B28: D25FLD | C28: Đồng hồ D25 Flodis | D28: Cái | F28: ='Nhập Kho'!Q29 -> 48 | G28: ='Xuất kho theo tháng'!CL28 -> 31 | H28: =(E28+F28)-G28 -> 17
B29: D32FLD | C29: Đồng hồ D32 Flodis | D29: Cái | F29: ='Nhập Kho'!Q30 -> 53 | G29: ='Xuất kho theo tháng'!CL29 -> 15 | H29: =(E29+F29)-G29 -> 38
B30: D40FLT | C30: Đồng hồ D40 Flostar | D30: Cái
F31: ='Nhập Kho'!Q32 | H31: =SUM(H6:H26) -> 527

Sheet Nhập Kho
B3: Mã hàng | C3: Tên hàng | D3: ĐVT | E3: Tháng 1 | F3: Tháng 2 | G3: Tháng 3 | H3: Tháng 4 | I3: Tháng 5 | J3: Tháng 6 | K3: Tháng 7 | L3: Tháng 8 | M3: Tháng 9 | N3: Tháng 10 | O3: Tháng 11 | P3: Tháng 12 | Q3: Cuối kỳ
E4: Số lượng | F4: Số lượng | G4: Số lượng | H4: Số lượng | I4: Số lượng | J4: Số lượng | K4: Số lượng | L4: Số lượng | M4: Số lượng | N4: Số lượng | O4: Số lượng | P4: Số lượng | Q4: Số lượng
A5: Tên kho : 02-Kho Văn phòng Công ty (20 )
B6: ĐH015 | C6: Đồng hồ D15 | D6: Cái | E6: =500+240 -> 740 | G6: 1000 | I6: 500 | Q6: =SUM(E6:P6) -> 2240
B7: ĐH015(SC) | C7: Đồng hồ sửa chữa 015 | D7: Cái | E7: =920+460 -> 1380 | F7: =920+460 -> 1380 | G7: 920 | H7: 710 | I7: 700 | J7: 700 | K7: 300 | L7: 400 | Q7: =SUM(E7:P7) -> 6490
B8: ĐH015(SC) | C8: Đồng hồ sửa chữa 015 đơn vị | D8: Cái | Q8: =SUM(E8:P8) -> 0
B9: ĐH015-TAC | C9: Đồng hồ Thái Aichi MAM-15 ( không kèm rắc co) | D9: Cái | Q9: =SUM(E9:P9) -> 0
B10: ĐH020 | C10: Đồng hồ D20 | D10: Cái | Q10: =SUM(E10:P10) -> 0
B11: ĐH025 | C11: Đồng hồ D25 | D11: Cái | Q11: =SUM(E11:P11) -> 0
B12: ĐH025(SC) | C12: Đồng hồ D25 (sửa chữa) | D12: Cái | Q12: =SUM(E12:P12) -> 0
B13: ĐH032 | C13: Đồng hồ D32 | D13: Cái | Q13: =SUM(E13:P13) -> 0
B14: ĐH032(SC) | C14: Đồng hồ D32 (sửa chữa) | D14: Cái | Q14: =SUM(E14:P14) -> 0
B15: ĐH040 | C15: Đồng hồ D40 | D15: Cái | E15: 10 | G15: 5 | I15: 15 | L15: 5 | Q15: =SUM(E15:P15) -> 35
B16: ĐH040(SC) | C16: Đồng hồ D40 (sửa chữa) | D16: Cái | E16: 3 | Q16: =SUM(E16:P16) -> 3
B17: ĐH040-ĐLL | C17: Đồng hồ đo lưu lượng Turbobar hiệu Bermad DN40 | D17: Bộ | E17: 1 | Q17: =SUM(E17:P17) -> 1
B18: ĐH050 | C18: Đồng hồ D50 | D18: Cái | E18: 4 | Q18: =SUM(E18:P18) -> 4
B19: ĐH050(SC) | C19: Đồng hồ D50 (sửa chữa) | D19: Cái | Q19: =SUM(E19:P19) -> 0
B20: ĐH050-BM | C20: Đồng hồ DN50 hiệu Bermad | D20: Cái | E20: 6 | Q20: =SUM(E20:P20) -> 6
B21: ĐH065 | C21: Đồng hồ D65 | D21: Cái | E21: =2+1 -> 3 | G21: 2 | Q21: =SUM(E21:P21) -> 5
B22: ĐH065-ĐLL | C22: Đồng hồ đo lưu lượng Turbobar hiệu Bermad DN65 | D22: Bộ | Q22: =SUM(E22:P22) -> 0
B23: ĐH080 | C23: Đồng hồ D80 | D23: Cái | E23: 4 | Q23: =SUM(E23:P23) -> 4
B24: ĐH100 | C24: Đồng hồ D100 | D24: Cái | E24: 3 | G24: 2 | I24: 2 | Q24: =SUM(E24:P24) -> 7
B25: ĐH150 | C25: Đồng hồ D150 | D25: Cái | E25: 2 | G25: 2 | Q25: =SUM(E25:P25) -> 4
B26: ĐH150-CTOR | C26: Đồng hồ nước DN150 CONTOR-Metcon Qn=150m3/h, cấp B (Pvđ: 4,5-300m3/h) | D26: Cái | E26: 1 | Q26: =SUM(E26:P26) -> 1
B27: ĐH200 | C27: Đồng hồ D200 | D27: Cái | E27: 2 | Q27: =SUM(E27:P27) -> 2
B28: ĐH15 | C28: Đồng hồ D15 metcon | D28: Cái | Q28: =SUM(E28:P28) -> 0
B29: D25FLD | C29: Đồng hồ D25 Flodis | D29: Cái | E29: 28 | G29: 5 | I29: 15 | Q29: =SUM(E29:P29) -> 48
B30: D32FLD | C30: Đồng hồ D32 Flodis | D30: Cái | E30: 13 | G30: 5 | I30: 35 | Q30: =SUM(E30:P30) -> 53

Sheet TP1
B3: Mã hàng | C3: Tên hàng | D3: ĐVT | E3: Tháng 1 | L3: Tháng 2 | S3: Tháng 3 | Z3: Tháng 4 | AG3: Tháng 5 | AN3: Tháng 6 | AU3: Tháng 7 | BB3: Tháng 8 | BI3: Tháng 9 | BP3: Tháng 10 | BW3: Tháng 11 | CD3: Tháng 12 | CK3: Cuối kỳ
E4: ĐH quay vòng | F4: Xuất ĐH | G4: ĐH ĐV gửi về | H4: Kiểm tra BH | J4: Kiểm đinh bất thường | L4: ĐH quay vòng | M4: Xuất ĐH | N4: ĐH ĐV gửi về | O4: Kiểm tra BH | Q4: Kiểm đinh bất thường | S4: ĐH quay vòng | T4: Xuất ĐH | U4: ĐH ĐV gửi về | V4: Kiểm tra BH | X4: Kiểm đinh bất thường | Z4: ĐH quay vòng | AA4: Xuất ĐH | AB4: ĐH ĐV gửi về | AC4: Kiểm tra BH | AE4: Kiểm đinh bất thường | AG4: ĐH quay vòng | AH4: Xuất ĐH | AI4: ĐH ĐV gửi về | AJ4: Kiểm tra BH | AL4: Kiểm đinh bất thường | AN4: ĐH quay vòng | AO4: Xuất ĐH | AP4: ĐH ĐV gửi về | AQ4: Kiểm tra BH | AS4: Kiểm đinh bất thường | AU4: ĐH quay vòng | AV4: Xuất ĐH | AW4: ĐH ĐV gửi về | AX4: Kiểm tra BH | AZ4: Kiểm đinh bất thường | BB4: ĐH quay vòng | BC4: Xuất ĐH | BD4: ĐH ĐV gửi về | BE4: Kiểm tra BH | BG4: Kiểm đinh bất thường | BI4: ĐH quay vòng | BJ4: Xuất ĐH | BK4: ĐH ĐV gửi về | BL4: Kiểm tra BH | BN4: Kiểm đinh bất thường | BP4: ĐH quay vòng | BQ4: Xuất ĐH | BR4: ĐH ĐV gửi về | BS4: Kiểm tra BH | BU4: Kiểm đinh bất thường | BW4: ĐH quay vòng | BX4: Xuất ĐH | BY4: ĐH ĐV gửi về | BZ4: Kiểm tra BH | CB4: Kiểm đinh bất thường | CD4: ĐH quay vòng | CE4: Xuất ĐH | CF4: ĐH ĐV gửi về | CG4: Kiểm tra BH | CI4: Kiểm đinh bất thường | CK4: ĐH quay vòng | CL4: Xuất ĐH | CM4: ĐH ĐV gửi về | CN4: Kiểm tra BH | CP4: Kiểm đinh bất thường
A5: Tên kho : 02-Kho Văn phòng Công ty | H5: Đạt(A duy) | I5: K đạt | J5: Đạt | K5: K đạt | O5: Đạt | P5: K đạt | Q5: Đạt | R5: K đạt | V5: Đạt | W5: K đạt | X5: Đạt | Y5: K đạt | AC5: Đạt | AD5: K đạt | AE5: Đạt | AF5: K đạt | AJ5: Đạt | AK5: K đạt | AL5: Đạt | AM5: K đạt | AQ5: Đạt | AR5: K đạt | AS5: Đạt | AT5: K đạt | AX5: Đạt | AY5: K đạt | AZ5: Đạt | BA5: K đạt | BE5: Đạt | BF5: K đạt | BG5: Đạt | BH5: K đạt | BL5: Đạt | BM5: K đạt | BN5: Đạt | BO5: K đạt | BS5: Đạt | BT5: K đạt | BU5: Đạt | BV5: K đạt | BZ5: Đạt | CA5: K đạt | CB5: Đạt | CC5: K đạt | CG5: Đạt | CH5: K đạt | CI5: Đạt | CJ5: K đạt | CN5: Đạt | CO5: K đạt | CP5: Đạt | CQ5: K đạt
B6: ĐH015 | C6: Đồng hồ D15 | D6: Cái | F6: 30 | M6: 30 | T6: 90 | AA6: 150 | AH6: 20 | AO6: 40 | AV6: 20 | BC6: 50 | CK6: =SUM(E6,L6,S6,Z6,AG6,AN6,AU6,BB6,BI6,BP6,BW6,CD6) -> 0 | CL6: =SUM(F6,M6,T6,AA6,AH6,AO6,AV6,BC6,BJ6,BQ6,BX6,CE6) -> 430 | CM6: =SUM(G6,N6,U6,AB6,AI6,AP6,AW6,BD6,BK6,BR6,BY6,CF6) -> 0 | CN6: =SUM(H6,O6,V6,AC6,AJ6,AQ6,AX6,BE6,BL6,BS6,BZ6,CG6) -> 0 | CO6: =SUM(I6,P6,W6,AD6,AK6,AR6,AY6,BF6,BM6,BT6,CA6,CH6) -> 0 | CP6: =SUM(J6,Q6,X6,AE6,AL6,AS6,AZ6,BG6,BN6,BU6,CB6,CI6) -> 0 | CQ6: =SUM(K6,R6,Y6,AF6,AM6,AT6,BA6,BH6,BO6,BV6,CC6,CJ6) -> 0
B7: ĐH015(SC) | C7: Đồng hồ sửa chữa 015 | D7: Cái | F7: 260 | G7: 260 | M7: 260 | N7: 260 | T7: 260 | U7: 32 | AA7: 100 | AB7: 328 | AH7: 200 | AI7: 240 | AO7: 200 | AV7: 200 | BC7: 200 | BD7: 131 | BJ7: 200 | CK7: =SUM(E7,L7,S7,Z7,AG7,AN7,AU7,BB7,BI7,BP7,BW7,CD7) -> 0 | CL7: =SUM(F7,M7,T7,AA7,AH7,AO7,AV7,BC7,BJ7,BQ7,BX7,CE7) -> 1880 | CM7: =SUM(G7,N7,U7,AB7,AI7,AP7,AW7,BD7,BK7,BR7,BY7,CF7) -> 1251 | CN7: =SUM(H7,O7,V7,AC7,AJ7,AQ7,AX7,BE7,BL7,BS7,BZ7,CG7) -> 0 | CO7: =SUM(I7,P7,W7,AD7,AK7,AR7,AY7,BF7,BM7,BT7,CA7,CH7) -> 0 | CP7: =SUM(J7,Q7,X7,AE7,AL7,AS7,AZ7,BG7,BN7,BU7,CB7,CI7) -> 0 | CQ7: =SUM(K7,R7,Y7,AF7,AM7,AT7,BA7,BH7,BO7,BV7,CC7,CJ7) -> 0
B8: ĐH015(SC) | C8: Đồng hồ sửa chữa 015 đơn vị | D8: Cái | CK8: =SUM(E8,L8,S8,Z8,AG8,AN8,AU8,BB8,BI8,BP8,BW8,CD8) -> 0 | CL8: =SUM(F8,M8,T8,AA8,AH8,AO8,AV8,BC8,BJ8,BQ8,BX8,CE8) -> 0 | CM8: =SUM(G8,N8,U8,AB8,AI8,AP8,AW8,BD8,BK8,BR8,BY8,CF8) -> 0 | CN8: =SUM(H8,O8,V8,AC8,AJ8,AQ8,AX8,BE8,BL8,BS8,BZ8,CG8) -> 0 | CO8: =SUM(I8,P8,W8,AD8,AK8,AR8,AY8,BF8,BM8,BT8,CA8,CH8) -> 0 | CP8: =SUM(J8,Q8,X8,AE8,AL8,AS8,AZ8,BG8,BN8,BU8,CB8,CI8) -> 0 | CQ8: =SUM(K8,R8,Y8,AF8,AM8,AT8,BA8,BH8,BO8,BV8,CC8,CJ8) -> 0
B9: ĐH015-TAC | C9: Đồng hồ Thái Aichi MAM-15 ( không kèm rắc co) | D9: Cái | CK9: =SUM(E9,L9,S9,Z9,AG9,AN9,AU9,BB9,BI9,BP9,BW9,CD9) -> 0 | CL9: =SUM(F9,M9,T9,AA9,AH9,AO9,AV9,BC9,BJ9,BQ9,BX9,CE9) -> 0 | CM9: =SUM(G9,N9,U9,AB9,AI9,AP9,AW9,BD9,BK9,BR9,BY9,CF9) -> 0 | CN9: =SUM(H9,O9,V9,AC9,AJ9,AQ9,AX9,BE9,BL9,BS9,BZ9,CG9) -> 0 | CO9: =SUM(I9,P9,W9,AD9,AK9,AR9,AY9,BF9,BM9,BT9,CA9,CH9) -> 0 | CP9: =SUM(J9,Q9,X9,AE9,AL9,AS9,AZ9,BG9,BN9,BU9,CB9,CI9) -> 0 | CQ9: =SUM(K9,R9,Y9,AF9,AM9,AT9,BA9,BH9,BO9,BV9,CC9,CJ9) -> 0
B10: ĐH020 | C10: Đồng hồ D20 | D10: Cái | CK10: =SUM(E10,L10,S10,Z10,AG10,AN10,AU10,BB10,BI10,BP10,BW10,CD10) -> 0 | CL10: =SUM(F10,M10,T10,AA10,AH10,AO10,AV10,BC10,BJ10,BQ10,BX10,CE10) -> 0 | CM10: =SUM(G10,N10,U10,AB10,AI10,AP10,AW10,BD10,BK10,BR10,BY10,CF10) -> 0 | CN10: =SUM(H10,O10,V10,AC10,AJ10,AQ10,AX10,BE10,BL10,BS10,BZ10,CG10) -> 0 | CO10: =SUM(I10,P10,W10,AD10,AK10,AR10,AY10,BF10,BM10,BT10,CA10,CH10) -> 0 | CP10: =SUM(J10,Q10,X10,AE10,AL10,AS10,AZ10,BG10,BN10,BU10,CB10,CI10) -> 0 | CQ10: =SUM(K10,R10,Y10,AF10,AM10,AT10,BA10,BH10,BO10,BV10,CC10,CJ10) -> 0
B11: ĐH025 | C11: Đồng hồ D25 | D11: Cái | CK11: =SUM(E11,L11,S11,Z11,AG11,AN11,AU11,BB11,BI11,BP11,BW11,CD11) -> 0 | CL11: =SUM(F11,M11,T11,AA11,AH11,AO11,AV11,BC11,BJ11,BQ11,BX11,CE11) -> 0 | CM11: =SUM(G11,N11,U11,AB11,AI11,AP11,AW11,BD11,BK11,BR11,BY11,CF11) -> 0 | CN11: =SUM(H11,O11,V11,AC11,AJ11,AQ11,#REF!,BE11,BL11,BS11,BZ11,CG11) -> #REF! | CO11: =SUM(I11,P11,W11,AD11,AK11,AR11,AY11,BF11,BM11,BT11,CA11,CH11) -> 0 | CP11: =SUM(J11,Q11,X11,AE11,AL11,AS11,AZ11,BG11,BN11,BU11,CB11,CI11) -> 0 | CQ11: =SUM(K11,R11,Y11,AF11,AM11,AT11,BA11,BH11,BO11,BV11,CC11,CJ11) -> 0
A12: Đồng hồ D25 | B12: ĐH025(SC) | C12: Đồng hồ D25 (sửa chữa) | D12: Cái | CK12: =SUM(E12,L12,S12,Z12,AG12,AN12,AU12,BB12,BI12,BP12,BW12,CD12) -> 0 | CL12: =SUM(F12,M12,T12,AA12,AH12,AO12,AV12,BC12,BJ12,BQ12,BX12,CE12) -> 0 | CM12: =SUM(G12,N12,U12,AB12,AI12,AP12,AW12,BD12,BK12,BR12,BY12,CF12) -> 0 | CN12: =SUM(H12,O12,V12,AC12,AJ12,AQ12,AX11,BE12,BL12,BS12,BZ12,CG12) -> 0 | CO12: =SUM(I12,P12,W12,AD12,AK12,AR12,AY12,BF12,BM12,BT12,CA12,CH12) -> 0 | CP12: =SUM(J12,Q12,X12,AE12,AL12,AS12,AZ12,BG12,BN12,BU12,CB12,CI12) -> 0 | CQ12: =SUM(K12,R12,Y12,AF12,AM12,AT12,BA12,BH12,BO12,BV12,CC12,CJ12) -> 0
B13: ĐH032 | C13: Đồng hồ D32 | D13: Cái | CK13: =SUM(E13,L13,S13,Z13,AG13,AN13,AU13,BB13,BI13,BP13,BW13,CD13) -> 0 | CL13: =SUM(F13,M13,T13,AA13,AH13,AO13,AV13,BC13,BJ13,BQ13,BX13,CE13) -> 0 | CM13: =SUM(G13,N13,U13,AB13,AI13,AP13,AW13,BD13,BK13,BR13,BY13,CF13) -> 0 | CN13: =SUM(H13,O13,V13,AC13,AJ13,AQ13,AX13,BE13,BL13,BS13,BZ13,CG13) -> 0 | CO13: =SUM(I13,P13,W13,AD13,AK13,AR13,AY13,BF13,BM13,BT13,CA13,CH13) -> 0 | CP13: =SUM(J13,Q13,X13,AE13,AL13,AS13,AZ13,BG13,BN13,BU13,CB13,CI13) -> 0 | CQ13: =SUM(K13,R13,Y13,AF13,AM13,AT13,BA13,BH13,BO13,BV13,CC13,CJ13) -> 0
B14: ĐH032(SC) | C14: Đồng hồ D32 (sửa chữa) | D14: Cái | CK14: =SUM(E14,L14,S14,Z14,AG14,AN14,AU14,BB14,BI14,BP14,BW14,CD14) -> 0 | CL14: =SUM(F14,M14,T14,AA14,AH14,AO14,AV14,BC14,BJ14,BQ14,BX14,CE14) -> 0 | CM14: =SUM(G14,N14,U14,AB14,AI14,AP14,AW14,BD14,BK14,BR14,BY14,CF14) -> 0 | CN14: =SUM(H14,O14,V14,AC14,AJ14,AQ14,AX14,BE14,BL14,BS14,BZ14,CG14) -> 0 | CO14: =SUM(I14,P14,W14,AD14,AK14,AR14,AY14,BF14,BM14,BT14,CA14,CH14) -> 0 | CP14: =SUM(J14,Q14,X14,AE14,AL14,AS14,AZ14,BG14,BN14,BU14,CB14,CI14) -> 0 | CQ14: =SUM(K14,R14,Y14,AF14,AM14,AT14,BA14,BH14,BO14,BV14,CC14,CJ14) -> 0
B15: ĐH040 | C15: Đồng hồ D40 | D15: Cái | M15: 1 | AO15: 1 | AV15: 4 | AW15: 3 | CK15: =SUM(E15,L15,S15,Z15,AG15,AN15,AU15,BB15,BI15,BP15,BW15,CD15) -> 0 | CL15: =SUM(F15,M15,T15,AA15,AH15,AO15,AV15,BC15,BJ15,BQ15,BX15,CE15) -> 6 | CM15: =SUM(G15,N15,U15,AB15,AI15,AP15,AW15,BD15,BK15,BR15,BY15,CF15) -> 3 | CN15: =SUM(H15,O15,V15,AC15,AJ15,AQ15,AX15,BE15,BL15,BS15,BZ15,CG15) -> 0 | CO15: =SUM(I15,P15,W15,AD15,AK15,AR15,AY15,BF15,BM15,BT15,CA15,CH15) -> 0 | CP15: =SUM(J15,Q15,X15,AE15,AL15,AS15,AZ15,BG15,BN15,BU15,CB15,CI15) -> 0 | CQ15: =SUM(K15,R15,Y15,AF15,AM15,AT15,BA15,BH15,BO15,BV15,CC15,CJ15) -> 0
B16: ĐH040(SC) | C16: Đồng hồ D40 (sửa chữa) | D16: Cái | N16: 1 | CK16: =SUM(E16,L16,S16,Z16,AG16,AN16,AU16,BB16,BI16,BP16,BW16,CD16) -> 0 | CL16: =SUM(F16,M16,T16,AA16,AH16,AO16,AV16,BC16,BJ16,BQ16,BX16,CE16) -> 0 | CM16: =SUM(G16,N16,U16,AB16,AI16,AP16,AW16,BD16,BK16,BR16,BY16,CF16) -> 1 | CN16: =SUM(H16,O16,V16,AC16,AJ16,AQ16,AX16,BE16,BL16,BS16,BZ16,CG16) -> 0 | CO16: =SUM(I16,P16,W16,AD16,AK16,AR16,AY16,BF16,BM16,BT16,CA16,CH16) -> 0 | CP16: =SUM(J16,Q16,X16,AE16,AL16,AS16,AZ16,BG16,BN16,BU16,CB16,CI16) -> 0 | CQ16: =SUM(K16,R16,Y16,AF16,AM16,AT16,BA16,BH16,BO16,BV16,CC16,CJ16) -> 0
B17: ĐH040-ĐLL | C17: Đồng hồ đo lưu lượng Turbobar hiệu Bermad DN40 | D17: Bộ | CK17: =SUM(E17,L17,S17,Z17,AG17,AN17,AU17,BB17,BI17,BP17,BW17,CD17) -> 0 | CL17: =SUM(F17,M17,T17,AA17,AH17,AO17,AV17,BC17,BJ17,BQ17,BX17,CE17) -> 0 | CM17: =SUM(G17,N17,U17,AB17,AI17,AP17,AW17,BD17,BK17,BR17,BY17,CF17) -> 0 | CN17: =SUM(H17,O17,V17,AC17,AJ17,AQ17,AX17,BE17,BL17,BS17,BZ17,CG17) -> 0 | CO17: =SUM(I17,P17,W17,AD17,AK17,AR17,AY17,BF17,BM17,BT17,CA17,CH17) -> 0 | CP17: =SUM(J17,Q17,X17,AE17,AL17,AS17,AZ17,BG17,BN17,BU17,CB17,CI17) -> 0 | CQ17: =SUM(K17,R17,Y17,AF17,AM17,AT17,BA17,BH17,BO17,BV17,CC17,CJ17) -> 0
B18: ĐH050 | C18: Đồng hồ D50 | D18: Cái | AW18: 1 | CK18: =SUM(E18,L18,S18,Z18,AG18,AN18,AU18,BB18,BI18,BP18,BW18,CD18) -> 0 | CL18: =SUM(F18,M18,T18,AA18,AH18,AO18,AV18,BC18,BJ18,BQ18,BX18,CE18) -> 0 | CM18: =SUM(G18,N18,U18,AB18,AI18,AP18,AW18,BD18,BK18,BR18,BY18,CF18) -> 1 | CN18: =SUM(H18,O18,V18,AC18,AJ18,AQ18,AX18,BE18,BL18,BS18,BZ18,CG18) -> 0 | CO18: =SUM(I18,P18,W18,AD18,AK18,AR18,AY18,BF18,BM18,BT18,CA18,CH18) -> 0 | CP18: =SUM(J18,Q18,X18,AE18,AL18,AS18,AZ18,BG18,BN18,BU18,CB18,CI18) -> 0 | CQ18: =SUM(K18,R18,Y18,AF18,AM18,AT18,BA18,BH18,BO18,BV18,CC18,CJ18) -> 0
B19: ĐH050(SC) | C19: Đồng hồ D50 (sửa chữa) | D19: Cái | CK19: =SUM(E19,L19,S19,Z19,AG19,AN19,AU19,BB19,BI19,BP19,BW19,CD19) -> 0 | CL19: =SUM(F19,M19,T19,AA19,AH19,AO19,AV19,BC19,BJ19,BQ19,BX19,CE19) -> 0 | CM19: =SUM(G19,N19,U19,AB19,AI19,AP19,AW19,BD19,BK19,BR19,BY19,CF19) -> 0 | CN19: =SUM(H19,O19,V19,AC19,AJ19,AQ19,AX19,BE19,BL19,BS19,BZ19,CG19) -> 0 | CO19: =SUM(I19,P19,W19,AD19,AK19,AR19,AY19,BF19,BM19,BT19,CA19,CH19) -> 0 | CP19: =SUM(J19,Q19,X19,AE19,AL19,AS19,AZ19,BG19,BN19,BU19,CB19,CI19) -> 0 | CQ19: =SUM(K19,R19,Y19,AF19,AM19,AT19,BA19,BH19,BO19,BV19,CC19,CJ19) -> 0
B20: ĐH050-BM | C20: Đồng hồ DN50 hiệu Bermad | D20: Cái | CK20: =SUM(E20,L20,S20,Z20,AG20,AN20,AU20,BB20,BI20,BP20,BW20,CD20) -> 0 | CL20: =SUM(F20,M20,T20,AA20,AH20,AO20,AV20,BC20,BJ20,BQ20,BX20,CE20) -> 0 | CM20: =SUM(G20,N20,U20,AB20,AI20,AP20,AW20,BD20,BK20,BR20,BY20,CF20) -> 0 | CN20: =SUM(H20,O20,V20,AC20,AJ20,AQ20,AX20,BE20,BL20,BS20,BZ20,CG20) -> 0 | CO20: =SUM(I20,P20,W20,AD20,AK20,AR20,AY20,BF20,BM20,BT20,CA20,CH20) -> 0 | CP20: =SUM(J20,Q20,X20,AE20,AL20,AS20,AZ20,BG20,BN20,BU20,CB20,CI20) -> 0 | CQ20: =SUM(K20,R20,Y20,AF20,AM20,AT20,BA20,BH20,BO20,BV20,CC20,CJ20) -> 0
B21: ĐH065 | C21: Đồng hồ D65 | D21: Cái | CK21: =SUM(E21,L21,S21,Z21,AG21,AN21,AU21,BB21,BI21,BP21,BW21,CD21) -> 0 | CL21: =SUM(F21,M21,T21,AA21,AH21,AO21,AV21,BC21,BJ21,BQ21,BX21,CE21) -> 0 | CM21: =SUM(G21,N21,U21,AB21,AI21,AP21,AW21,BD21,BK21,BR21,BY21,CF21) -> 0 | CN21: =SUM(H21,O21,V21,AC21,AJ21,AQ21,AX21,BE21,BL21,BS21,BZ21,CG21) -> 0 | CO21: =SUM(I21,P21,W21,AD21,AK21,AR21,AY21,BF21,BM21,BT21,CA21,CH21) -> 0 | CP21: =SUM(J21,Q21,X21,AE21,AL21,AS21,AZ21,BG21,BN21,BU21,CB21,CI21) -> 0 | CQ21: =SUM(K21,R21,Y21,AF21,AM21,AT21,BA21,BH21,BO21,BV21,CC21,CJ21) -> 0
B22: ĐH065-ĐLL | C22: Đồng hồ đo lưu lượng Turbobar hiệu Bermad DN65 | D22: Bộ | CK22: =SUM(E22,L22,S22,Z22,AG22,AN22,AU22,BB22,BI22,BP22,BW22,CD22) -> 0 | CL22: =SUM(F22,M22,T22,AA22,AH22,AO22,AV22,BC22,BJ22,BQ22,BX22,CE22) -> 0 | CM22: =SUM(G22,N22,U22,AB22,AI22,AP22,AW22,BD22,BK22,BR22,BY22,CF22) -> 0 | CN22: =SUM(H22,O22,V22,AC22,AJ22,AQ22,AX22,BE22,BL22,BS22,BZ22,CG22) -> 0 | CO22: =SUM(I22,P22,W22,AD22,AK22,AR22,AY22,BF22,BM22,BT22,CA22,CH22) -> 0 | CP22: =SUM(J22,Q22,X22,AE22,AL22,AS22,AZ22,BG22,BN22,BU22,CB22,CI22) -> 0 | CQ22: =SUM(K22,R22,Y22,AF22,AM22,AT22,BA22,BH22,BO22,BV22,CC22,CJ22) -> 0
B23: ĐH080 | C23: Đồng hồ D80 | D23: Cái | AH23: 1 | CK23: =SUM(E23,L23,S23,Z23,AG23,AN23,AU23,BB23,BI23,BP23,BW23,CD23) -> 0 | CL23: =SUM(F23,M23,T23,AA23,AH23,AO23,AV23,BC23,BJ23,BQ23,BX23,CE23) -> 1 | CM23: =SUM(G23,N23,U23,AB23,AI23,AP23,AW23,BD23,BK23,BR23,BY23,CF23) -> 0 | CN23: =SUM(H23,O23,V23,AC23,AJ23,AQ23,AX23,BE23,BL23,BS23,BZ23,CG23) -> 0 | CO23: =SUM(I23,P23,W23,AD23,AK23,AR23,AY23,BF23,BM23,BT23,CA23,CH23) -> 0 | CP23: =SUM(J23,Q23,X23,AE23,AL23,AS23,AZ23,BG23,BN23,BU23,CB23,CI23) -> 0 | CQ23: =SUM(K23,R23,Y23,AF23,AM23,AT23,BA23,BH23,BO23,BV23,CC23,CJ23) -> 0
B24: ĐH100 | C24: Đồng hồ D100 | D24: Cái | CK24: =SUM(E24,L24,S24,Z24,AG24,AN24,AU24,BB24,BI24,BP24,BW24,CD24) -> 0 | CL24: =SUM(F24,M24,T24,AA24,AH24,AO24,AV24,BC24,BJ24,BQ24,BX24,CE24) -> 0 | CM24: =SUM(G24,N24,U24,AB24,AI24,AP24,AW24,BD24,BK24,BR24,BY24,CF24) -> 0 | CN24: =SUM(H24,O24,V24,AC24,AJ24,AQ24,AX24,BE24,BL24,BS24,BZ24,CG24) -> 0 | CO24: =SUM(I24,P24,W24,AD24,AK24,AR24,AY24,BF24,BM24,BT24,CA24,CH24) -> 0 | CP24: =SUM(J24,Q24,X24,AE24,AL24,AS24,AZ24,BG24,BN24,BU24,CB24,CI24) -> 0 | CQ24: =SUM(K24,R24,Y24,AF24,AM24,AT24,BA24,BH24,BO24,BV24,CC24,CJ24) -> 0
B25: ĐH150 | C25: Đồng hồ D150 | D25: Cái | CK25: =SUM(E25,L25,S25,Z25,AG25,AN25,AU25,BB25,BI25,BP25,BW25,CD25) -> 0 | CL25: =SUM(F25,M25,T25,AA25,AH25,AO25,AV25,BC25,BJ25,BQ25,BX25,CE25) -> 0 | CM25: =SUM(G25,N25,U25,AB25,AI25,AP25,AW25,BD25,BK25,BR25,BY25,CF25) -> 0 | CN25: =SUM(H25,O25,V25,AC25,AJ25,AQ25,AX25,BE25,BL25,BS25,BZ25,CG25) -> 0 | CO25: =SUM(I25,P25,W25,AD25,AK25,AR25,AY25,BF25,BM25,BT25,CA25,CH25) -> 0 | CP25: =SUM(J25,Q25,X25,AE25,AL25,AS25,AZ25,BG25,BN25,BU25,CB25,CI25) -> 0 | CQ25: =SUM(K25,R25,Y25,AF25,AM25,AT25,BA25,BH25,BO25,BV25,CC25,CJ25) -> 0
B26: ĐH150-CTOR | C26: Đồng hồ nước DN150 CONTOR-Metcon Qn=150m3/h, cấp B (Pvđ: 4,5-300m3/h) | D26: Cái | CK26: =SUM(E26,L26,S26,Z26,AG26,AN26,AU26,BB26,BI26,BP26,BW26,CD26) -> 0 | CL26: =SUM(F26,M26,T26,AA26,AH26,AO26,AV26,BC26,BJ26,BQ26,BX26,CE26) -> 0 | CM26: =SUM(G26,N26,U26,AB26,AI26,AP26,AW26,BD26,BK26,BR26,BY26,CF26) -> 0 | CN26: =SUM(H26,O26,V26,AC26,AJ26,AQ26,AX26,BE26,BL26,BS26,BZ26,CG26) -> 0 | CO26: =SUM(I26,P26,W26,AD26,AK26,AR26,AY26,BF26,BM26,BT26,CA26,CH26) -> 0 | CP26: =SUM(J26,Q26,X26,AE26,AL26,AS26,AZ26,BG26,BN26,BU26,CB26,CI26) -> 0 | CQ26: =SUM(K26,R26,Y26,AF26,AM26,AT26,BA26,BH26,BO26,BV26,CC26,CJ26) -> 0
B27: ĐH200 | C27: Đồng hồ D200 | D27: Cái | CK27: =SUM(E27,L27,S27,Z27,AG27,AN27,AU27,BB27,BI27,BP27,BW27,CD27) -> 0 | CL27: =SUM(F27,M27,T27,AA27,AH27,AO27,AV27,BC27,BJ27,BQ27,BX27,CE27) -> 0 | CM27: =SUM(G27,N27,U27,AB27,AI27,AP27,AW27,BD27,BK27,BR27,BY27,CF27) -> 0 | CN27: =SUM(H27,O27,V27,AC27,AJ27,AQ27,AX27,BE27,BL27,BS27,BZ27,CG27) -> 0 | CO27: =SUM(I27,P27,W27,AD27,AK27,AR27,AY27,BF27,BM27,BT27,CA27,CH27) -> 0 | CP27: =SUM(J27,Q27,X27,AE27,AL27,AS27,AZ27,BG27,BN27,BU27,CB27,CI27) -> 0 | CQ27: =SUM(K27,R27,Y27,AF27,AM27,AT27,BA27,BH27,BO27,BV27,CC27,CJ27) -> 0
B28: D25FLD | C28: Đồng hồ D25 Flodis | D28: Cái | M28: 2 | N28: 1 | AA28: 1 | AB28: 1 | AO28: 3 | AP28: 1 | AV28: 4 | AW28: 1 | CK28: =SUM(E28,L28,S28,Z28,AG28,AN28,AU28,BB28,BI28,BP28,BW28,CD28) -> 0 | CL28: =SUM(F28,M28,T28,AA28,AH28,AO28,AV28,BC28,BJ28,BQ28,BX28,CE28) -> 10 | CM28: =SUM(G28,N28,U28,AB28,AI28,AP28,AW28,BD28,BK28,BR28,BY28,CF28) -> 4 | CN28: =SUM(H28,O28,V28,AC28,AJ28,AQ28,AX28,BE28,BL28,BS28,BZ28,CG28) -> 0 | CO28: =SUM(I28,P28,W28,AD28,AK28,AR28,AY28,BF28,BM28,BT28,CA28,CH28) -> 0 | CP28: =SUM(J28,Q28,X28,AE28,AL28,AS28,AZ28,BG28,BN28,BU28,CB28,CI28) -> 0 | CQ28: =SUM(K28,R28,Y28,AF28,AM28,AT28,BA28,BH28,BO28,BV28,CC28,CJ28) -> 0
B29: D32FLD | C29: Đồng hồ D32 Flodis | D29: Cái | AH29: 1 | AI29: 1 | AO29: 1 | AV29: 2 | AW29: 3 | CK29: =SUM(E29,L29,S29,Z29,AG29,AN29,AU29,BB29,BI29,BP29,BW29,CD29) -> 0 | CL29: =SUM(F29,M29,T29,AA29,AH29,AO29,AV29,BC29,BJ29,BQ29,BX29,CE29) -> 4 | CM29: =SUM(G29,N29,U29,AB29,AI29,AP29,AW29,BD29,BK29,BR29,BY29,CF29) -> 4 | CN29: =SUM(H29,O29,V29,AC29,AJ29,AQ29,AX29,BE29,BL29,BS29,BZ29,CG29) -> 0 | CO29: =SUM(I29,P29,W29,AD29,AK29,AR29,AY29,BF29,BM29,BT29,CA29,CH29) -> 0 | CP29: =SUM(J29,Q29,X29,AE29,AL29,AS29,AZ29,BG29,BN29,BU29,CB29,CI29) -> 0 | CQ29: =SUM(K29,R29,Y29,AF29,AM29,AT29,BA29,BH29,BO29,BV29,CC29,CJ29) -> 0
B30: D40FLT | C30: Đồng hồ D40 Flostar | D30: Cái | CK30: =SUM(E30,L30,S30,Z30,AG30,AN30,AU30,BB30,BI30,BP30,BW30,CD30) -> 0 | CL30: =SUM(F30,M30,T30,AA30,AH30,AO30,AV30,BC30,BJ30,BQ30,BX30,CE30) -> 0 | CM30: =SUM(G30,N30,U30,AB30,AI30,AP30,AW30,BD30,BK30,BR30,BY30,CF30) -> 0 | CN30: =SUM(H30,O30,V30,AC30,AJ30,AQ30,AX30,BE30,BL30,BS30,BZ30,CG30) -> 0 | CO30: =SUM(I30,P30,W30,AD30,AK30,AR30,AY30,BF30,BM30,BT30,CA30,CH30) -> 0 | CP30: =SUM(J30,Q30,X30,AE30,AL30,AS30,AZ30,BG30,BN30,BU30,CB30,CI30) -> 0 | CQ30: =SUM(K30,R30,Y30,AF30,AM30,AT30,BA30,BH30,BO30,BV30,CC30,CJ30) -> 0
E31: =SUM(E6:E27) -> 0 | F31: =SUM(F6:F29) -> 290 | G31: =SUM(G6:G27) -> 260 | H31: =SUM(H6:H27) -> 0 | I31: =SUM(I6:I27) -> 0 | J31: =SUM(J6:J27) -> 0 | K31: =SUM(K6:K27) -> 0 | L31: =SUM(L6:L27) -> 0 | M31: =SUM(M6:M27) -> 291 | N31: =SUM(N6:N27) -> 261 | ... Z31: =SUM(Z6:Z27) -> 0 | AA31: =SUM(AA6:AA29) -> 251 | AB31: =SUM(AB6:AB27) -> 328 | AC31: =SUM(AC6:AC27) -> 0 | AD31: =SUM(AD6:AD27) -> 0 | AE31: =SUM(AE6:AE27) -> 0 | AF31: =SUM(AF6:AF27) -> 0 | AG31: =SUM(AG6:AG27) -> 0 | AH31: =SUM(AH6:AH29) -> 222 | AI31: =SUM(AI6:AI27) -> 240 | AJ31: =SUM(AJ6:AJ27) -> 0 | AK31: =SUM(AK6:AK27) -> 0 | AL31: =SUM(AL6:AL27) -> 0 | AM31: =SUM(AM6:AM27) -> 0 | AN31: =SUM(AN6:AN27) -> 0 | AO31: =SUM(AO6:AO29) -> 245 | AP31: =SUM(AP6:AP27) -> 0 | AQ31: =SUM(AQ6:AQ27) -> 0 | AR31: =SUM(AR6:AR27) -> 0 | AS31: =SUM(AS6:AS27) -> 0 | AT31: =SUM(AT6:AT27) -> 0 | AU31: =SUM(AU6:AU27) -> 0 | AV31: =SUM(AV6:AV29) -> 230 | AW31: =SUM(AW6:AW27) -> 4 | AX31: =SUM(AX6:AX27) -> 0 | AY31: =SUM(AY6:AY27) -> 0 | AZ31: =SUM(AZ6:AZ27) -> 0 | BA31: =SUM(BA6:BA27) -> 0 | BB31: =SUM(BB6:BB27) -> 0 | BC31: =SUM(BC6:BC29) -> 250 | BD31: =SUM(BD6:BD27) -> 131 | BE31: =SUM(BE6:BE27) -> 0 | BF31: =SUM(BF6:BF27) -> 0 | BG31: =SUM(BG6:BG27) -> 0 | BH31: =SUM(BH6:BH27) -> 0 | BI31: =SUM(BI6:BI27) -> 0 | BJ31: =SUM(BJ6:BJ29) -> 200 | BK31: =SUM(BK6:BK27) -> 0 | BL31: =SUM(BL6:BL27) -> 0 | BM31: =SUM(BM6:BM27) -> 0 | BN31: =SUM(BN6:BN27) -> 0 | BO31: =SUM(BO6:BO27) -> 0 | BP31: =SUM(BP6:BP27) -> 0 | BQ31: =SUM(BQ6:BQ29) -> 0 | BR31: =SUM(BR6:BR27) -> 0 | BS31: =SUM(BS6:BS27) -> 0 | BT31: =SUM(BT6:BT27) -> 0 | BU31: =SUM(BU6:BU27) -> 0 | BV31: =SUM(BV6:BV27) -> 0 | BW31: =SUM(BW6:BW27) -> 0 | BX31: =SUM(BX6:BX29) -> 0 | BY31: =SUM(BY6:BY27) -> 0 | BZ31: =SUM(BZ6:BZ27) -> 0 | CA31: =SUM(CA6:CA27) -> 0 | CB31: =SUM(CB6:CB27) -> 0 | CC31: =SUM(CC6:CC27) -> 0 | CD31: =SUM(CD6:CD27) -> 0 | CE31: =SUM(CE6:CE29) -> 0 | CF31: =SUM(CF6:CF27) -> 0 | CG31: =SUM(CG6:CG27) -> 0 | CH31: =SUM(CH6:CH27) -> 0 | CI31: =SUM(CI6:CI27) -> 0 | CJ31: =SUM(CJ6:CJ27) -> 0 | CK31: =SUM(CK6:CK27) -> 0 | CL31: =SUM(CL6:CL29) -> 2331 | CM31: =SUM(CM6:CM27) -> 1256 | CN31: =SUM(CN6:CN27) -> #REF! | CO31: =SUM(CO6:CO27) -> 0 | CP31: =SUM(CP6:CP27) -> 0 | CQ31: =SUM(CQ6:CQ27) -> 0

Sheet TP2
B3: Mã hàng | C3: Tên hàng | D3: ĐVT | E3: Tháng 1 | L3: Tháng 2 | S3: Tháng 3 | Z3: Tháng 4 | AG3: Tháng 5 | AN3: Tháng 6 | AU3: Tháng 7 | BB3: Tháng 8 | BI3: Tháng 9 | BP3: Tháng 10 | BW3: Tháng 11 | CD3: Tháng 12 | CK3: Cuối kỳ
E4: ĐH quay vòng | F4: Xuất ĐH | G4: ĐH ĐV gửi về | H4: Kiểm tra BH | J4: Kiểm đinh bất thường | L4: ĐH quay vòng | M4: Xuất ĐH | N4: ĐH ĐV gửi về | O4: Kiểm tra BH | Q4: Kiểm đinh bất thường | S4: ĐH quay vòng | T4: Xuất ĐH | U4: ĐH ĐV gửi về | V4: Kiểm tra BH | X4: Kiểm đinh bất thường | Z4: ĐH quay vòng | AA4: Xuất ĐH | AB4: ĐH ĐV gửi về | AC4: Kiểm tra BH | AE4: Kiểm đinh bất thường | AG4: ĐH quay vòng | AH4: Xuất ĐH | AI4: ĐH ĐV gửi về | AJ4: Kiểm tra BH | AL4: Kiểm đinh bất thường | AN4: ĐH quay vòng | AO4: Xuất ĐH | AP4: ĐH ĐV gửi về | AQ4: Kiểm tra BH | AS4: Kiểm đinh bất thường | AU4: ĐH quay vòng | AV4: Xuất ĐH | AW4: ĐH ĐV gửi về | AX4: Kiểm tra BH | AZ4: Kiểm đinh bất thường | BB4: ĐH quay vòng | BC4: Xuất ĐH | BD4: ĐH ĐV gửi về | BE4: Kiểm tra BH | BG4: Kiểm đinh bất thường | BI4: ĐH quay vòng | BJ4: Xuất ĐH | BK4: ĐH ĐV gửi về | BL4: Kiểm tra BH | BN4: Kiểm đinh bất thường | BP4: ĐH quay vòng | BQ4: Xuất ĐH | BR4: ĐH ĐV gửi về | BS4: Kiểm tra BH | BU4: Kiểm đinh bất thường | BW4: ĐH quay vòng | BX4: Xuất ĐH | BY4: ĐH ĐV gửi về | BZ4: Kiểm tra BH | CB4: Kiểm đinh bất thường | CD4: ĐH quay vòng | CE4: Xuất ĐH | CF4: ĐH ĐV gửi về | CG4: Kiểm tra BH | CI4: Kiểm đinh bất thường | CK4: ĐH quay vòng | CL4: Xuất ĐH | CM4: ĐH ĐV gửi về | CN4: Kiểm tra BH | CP4: Kiểm đinh bất thường
A5: Tên kho : 02-Kho Văn phòng Công ty | H5: Đạt | I5: K đạt | J5: Đạt | K5: K đạt | O5: Đạt | P5: K đạt | Q5: Đạt | R5: K đạt | V5: Đạt | W5: K đạt | X5: Đạt | Y5: K đạt | AC5: Đạt | AD5: K đạt | AE5: Đạt | AF5: K đạt | AJ5: Đạt | AK5: K đạt | AL5: Đạt | AM5: K đạt | AQ5: Đạt | AR5: K đạt | AS5: Đạt | AT5: K đạt | AX5: Đạt | AY5: K đạt | AZ5: Đạt | BA5: K đạt | BE5: Đạt | BF5: K đạt | BG5: Đạt | BH5: K đạt | BL5: Đạt | BM5: K đạt | BN5: Đạt | BO5: K đạt | BS5: Đạt | BT5: K đạt | BU5: Đạt | BV5: K đạt | BZ5: Đạt | CA5: K đạt | CB5: Đạt | CC5: K đạt | CG5: Đạt | CH5: K đạt | CI5: Đạt | CJ5: K đạt | CN5: Đạt | CO5: K đạt | CP5: Đạt | CQ5: K đạt
B6: ĐH015 | C6: Đồng hồ D15 (Mới) | D6: Cái | F6: 20 | T6: 50 | AA6: 120 | AH6: 20 | AO6: 20 | AV6: 20 | BC6: 10 | CK6: =SUM(E6,L6,S6,Z6,AG6,AN6,AU6,BB6,BI6,BP6,BW6,CD6) -> 0 | CL6: =SUM(F6,M6,T6,AA6,AH6,AO6,AV6,BC6,BJ6,BQ6,BX6,CE6) -> 260 | CM6: =SUM(G6,N6,U6,AB6,AI6,AP6,AW6,BD6,BK6,BR6,BY6,CF6) -> 0 | CN6: =SUM(H6,O6,V6,AC6,AJ6,AQ6,AX6,BE6,BL6,BS6,BZ6,CG6) -> 0 | CO6: =SUM(I6,P6,W6,AD6,AK6,AR6,AY6,BF6,BM6,BT6,CA6,CH6) -> 0 | CP6: =SUM(J6,Q6,X6,AE6,AL6,AS6,AZ6,BG6,BN6,BU6,CB6,CI6) -> 0 | CQ6: =SUM(K6,R6,Y6,AF6,AM6,AT6,BA6,BH6,BO6,BV6,CC6,CJ6) -> 0
B7: ĐH015(SC) | C7: Đồng hồ sửa chữa 015 | D7: Cái | F7: 110 | M7: 110 | N7: 110 | T7: 110 | AA7: 110 | AB7: 170 | AH7: 10 | AI7: 10 | AO7: 90 | AP7: 90 | AV7: 90 | AW7: 90 | BC7: 90 | BD7: 90 | BJ7: 90 | CK7: =SUM(E7,L7,S7,Z7,AG7,AN7,AU7,BB7,BI7,BP7,BW7,CD7) -> 0 | CL7: =SUM(F7,M7,T7,AA7,AH7,AO7,AV7,BC7,BJ7,BQ7,BX7,CE7) -> 810 | CM7: =SUM(G7,N7,U7,AB7,AI7,AP7,AW7,BD7,BK7,BR7,BY7,CF7) -> 560 | CN7: =SUM(H7,O7,V7,AC7,AJ7,AQ7,AX7,BE7,BL7,BS7,BZ7,CG7) -> 0 | CO7: =SUM(I7,P7,W7,AD7,AK7,AR7,AY7,BF7,BM7,BT7,CA7,CH7) -> 0 | CP7: =SUM(J7,Q7,X7,AE7,AL7,AS7,AZ7,BG7,BN7,BU7,CB7,CI7) -> 0 | CQ7: =SUM(K7,R7,Y7,AF7,AM7,AT7,BA7,BH7,BO7,BV7,CC7,CJ7) -> 0
B8: ĐH015(SC) | C8: Đồng hồ sửa chữa 015 đơn vị | D8: Cái | CK8: =SUM(E8,L8,S8,Z8,AG8,AN8,AU8,BB8,BI8,BP8,BW8,CD8) -> 0 | CL8: =SUM(F8,M8,T8,AA8,AH8,AO8,AV8,BC8,BJ8,BQ8,BX8,CE8) -> 0 | CM8: =SUM(G8,N8,U8,AB8,AI8,AP8,AW8,BD8,BK8,BR8,BY8,CF8) -> 0 | CN8: =SUM(H8,O8,V8,AC8,AJ8,AQ8,AX8,BE8,BL8,BS8,BZ8,CG8) -> 0 | CO8: =SUM(I8,P8,W8,AD8,AK8,AR8,AY8,BF8,BM8,BT8,CA8,CH8) -> 0 | CP8: =SUM(J8,Q8,X8,AE8,AL8,AS8,AZ8,BG8,BN8,BU8,CB8,CI8) -> 0 | CQ8: =SUM(K8,R8,Y8,AF8,AM8,AT8,BA8,BH8,BO8,BV8,CC8,CJ8) -> 0
B9: ĐH015-TAC | C9: Đồng hồ Thái Aichi MAM-15 ( không kèm rắc co) | D9: Cái | CK9: =SUM(E9,L9,S9,Z9,AG9,AN9,AU9,BB9,BI9,BP9,BW9,CD9) -> 0 | CL9: =SUM(F9,M9,T9,AA9,AH9,AO9,AV9,BC9,BJ9,BQ9,BX9,CE9) -> 0 | CM9: =SUM(G9,N9,U9,AB9,AI9,AP9,AW9,BD9,BK9,BR9,BY9,CF9) -> 0 | CN9: =SUM(H9,O9,V9,AC9,AJ9,AQ9,AX9,BE9,BL9,BS9,BZ9,CG9) -> 0 | CO9: =SUM(I9,P9,W9,AD9,AK9,AR9,AY9,BF9,BM9,BT9,CA9,CH9) -> 0 | CP9: =SUM(J9,Q9,X9,AE9,AL9,AS9,AZ9,BG9,BN9,BU9,CB9,CI9) -> 0 | CQ9: =SUM(K9,R9,Y9,AF9,AM9,AT9,BA9,BH9,BO9,BV9,CC9,CJ9) -> 0
B10: ĐH020 | C10: Đồng hồ D20 | D10: Cái | CK10: =SUM(E10,L10,S10,Z10,AG10,AN10,AU10,BB10,BI10,BP10,BW10,CD10) -> 0 | CL10: =SUM(F10,M10,T10,AA10,AH10,AO10,AV10,BC10,BJ10,BQ10,BX10,CE10) -> 0 | CM10: =SUM(G10,N10,U10,AB10,AI10,AP10,AW10,BD10,BK10,BR10,BY10,CF10) -> 0 | CN10: =SUM(H10,O10,V10,AC10,AJ10,AQ10,AX10,BE10,BL10,BS10,BZ10,CG10) -> 0 | CO10: =SUM(I10,P10,W10,AD10,AK10,AR10,AY10,BF10,BM10,BT10,CA10,CH10) -> 0 | CP10: =SUM(J10,Q10,X10,AE10,AL10,AS10,AZ10,BG10,BN10,BU10,CB10,CI10) -> 0 | CQ10: =SUM(K10,R10,Y10,AF10,AM10,AT10,BA10,BH10,BO10,BV10,CC10,CJ10) -> 0
B11: ĐH025 | C11: Đồng hồ D25 | D11: Cái | CK11: =SUM(E11,L11,S11,Z11,AG11,AN11,AU11,BB11,BI11,BP11,BW11,CD11) -> 0 | CL11: =SUM(F11,M11,T11,AA11,AH11,AO11,AV11,BC11,BJ11,BQ11,BX11,CE11) -> 0 | CM11: =SUM(G11,N11,U11,AB11,AI11,AP11,AW11,BD11,BK11,BR11,BY11,CF11) -> 0 | CN11: =SUM(H11,O11,V11,AC11,AJ11,AQ11,AX11,BE11,BL11,BS11,BZ11,CG11) -> 0 | CO11: =SUM(I11,P11,W11,AD11,AK11,AR11,AY11,BF11,BM11,BT11,CA11,CH11) -> 0 | CP11: =SUM(J11,Q11,X11,AE11,AL11,AS11,AZ11,BG11,BN11,BU11,CB11,CI11) -> 0 | CQ11: =SUM(K11,R11,Y11,AF11,AM11,AT11,BA11,BH11,BO11,BV11,CC11,CJ11) -> 0
B12: ĐH025(SC) | C12: Đồng hồ D25 (sửa chữa) | D12: Cái | CK12: =SUM(E12,L12,S12,Z12,AG12,AN12,AU12,BB12,BI12,BP12,BW12,CD12) -> 0 | CL12: =SUM(F12,M12,T12,AA12,AH12,AO12,AV12,BC12,BJ12,BQ12,BX12,CE12) -> 0 | CM12: =SUM(G12,N12,U12,AB12,AI12,AP12,AW12,BD12,BK12,BR12,BY12,CF12) -> 0 | CN12: =SUM(H12,O12,V12,AC12,AJ12,AQ12,AX12,BE12,BL12,BS12,BZ12,CG12) -> 0 | CO12: =SUM(I12,P12,W12,AD12,AK12,AR12,AY12,BF12,BM12,BT12,CA12,CH12) -> 0 | CP12: =SUM(J12,Q12,X12,AE12,AL12,AS12,AZ12,BG12,BN12,BU12,CB12,CI12) -> 0 | CQ12: =SUM(K12,R12,Y12,AF12,AM12,AT12,BA12,BH12,BO12,BV12,CC12,CJ12) -> 0
B13: ĐH032 | C13: Đồng hồ D32 | D13: Cái | CK13: =SUM(E13,L13,S13,Z13,AG13,AN13,AU13,BB13,BI13,BP13,BW13,CD13) -> 0 | CL13: =SUM(F13,M13,T13,AA13,AH13,AO13,AV13,BC13,BJ13,BQ13,BX13,CE13) -> 0 | CM13: =SUM(G13,N13,U13,AB13,AI13,AP13,AW13,BD13,BK13,BR13,BY13,CF13) -> 0 | CN13: =SUM(H13,O13,V13,AC13,AJ13,AQ13,AX13,BE13,BL13,BS13,BZ13,CG13) -> 0 | CO13: =SUM(I13,P13,W13,AD13,AK13,AR13,AY13,BF13,BM13,BT13,CA13,CH13) -> 0 | CP13: =SUM(J13,Q13,X13,AE13,AL13,AS13,AZ13,BG13,BN13,BU13,CB13,CI13) -> 0 | CQ13: =SUM(K13,R13,Y13,AF13,AM13,AT13,BA13,BH13,BO13,BV13,CC13,CJ13) -> 0
B14: ĐH032(SC) | C14: Đồng hồ D32 (sửa chữa) | D14: Cái | CK14: =SUM(E14,L14,S14,Z14,AG14,AN14,AU14,BB14,BI14,BP14,BW14,CD14) -> 0 | CL14: =SUM(F14,M14,T14,AA14,AH14,AO14,AV14,BC14,BJ14,BQ14,BX14,CE14) -> 0 | CM14: =SUM(G14,N14,U14,AB14,AI14,AP14,AW14,BD14,BK14,BR14,BY14,CF14) -> 0 | CN14: =SUM(H14,O14,V14,AC14,AJ14,AQ14,AX14,BE14,BL14,BS14,BZ14,CG14) -> 0 | CO14: =SUM(I14,P14,W14,AD14,AK14,AR14,AY14,BF14,BM14,BT14,CA14,CH14) -> 0 | CP14: =SUM(J14,Q14,X14,AE14,AL14,AS14,AZ14,BG14,BN14,BU14,CB14,CI14) -> 0 | CQ14: =SUM(K14,R14,Y14,AF14,AM14,AT14,BA14,BH14,BO14,BV14,CC14,CJ14) -> 0
B15: ĐH040 | C15: Đồng hồ D40 | D15: Cái | F15: 2 | M15: 1 | T15: 2 | AO15: 1 | AP15: 1 | BC15: 1 | BD15: 1 | CK15: =SUM(E15,L15,S15,Z15,AG15,AN15,AU15,BB15,BI15,BP15,BW15,CD15) -> 0 | CL15: =SUM(F15,M15,T15,AA15,AH15,AO15,AV15,BC15,BJ15,BQ15,BX15,CE15) -> 7 | CM15: =SUM(G15,N15,U15,AB15,AI15,AP15,AW15,BD15,BK15,BR15,BY15,CF15) -> 2 | CN15: =SUM(H15,O15,V15,AC15,AJ15,AQ15,AX15,BE15,BL15,BS15,BZ15,CG15) -> 0 | CO15: =SUM(I15,P15,W15,AD15,AK15,AR15,AY15,BF15,BM15,BT15,CA15,CH15) -> 0 | CP15: =SUM(J15,Q15,X15,AE15,AL15,AS15,AZ15,BG15,BN15,BU15,CB15,CI15) -> 0 | CQ15: =SUM(K15,R15,Y15,AF15,AM15,AT15,BA15,BH15,BO15,BV15,CC15,CJ15) -> 0
B16: ĐH040(SC) | C16: Đồng hồ D40 (sửa chữa) | D16: Cái | N16: 1 | CK16: =SUM(E16,L16,S16,Z16,AG16,AN16,AU16,BB16,BI16,BP16,BW16,CD16) -> 0 | CL16: =SUM(F16,M16,T16,AA16,AH16,AO16,AV16,BC16,BJ16,BQ16,BX16,CE16) -> 0 | CM16: =SUM(G16,N16,U16,AB16,AI16,AP16,AW16,BD16,BK16,BR16,BY16,CF16) -> 1 | CN16: =SUM(H16,O16,V16,AC16,AJ16,AQ16,AX16,BE16,BL16,BS16,BZ16,CG16) -> 0 | CO16: =SUM(I16,P16,W16,AD16,AK16,AR16,AY16,BF16,BM16,BT16,CA16,CH16) -> 0 | CP16: =SUM(J16,Q16,X16,AE16,AL16,AS16,AZ16,BG16,BN16,BU16,CB16,CI16) -> 0 | CQ16: =SUM(K16,R16,Y16,AF16,AM16,AT16,BA16,BH16,BO16,BV16,CC16,CJ16) -> 0
B17: ĐH040-ĐLL | C17: Đồng hồ đo lưu lượng Turbobar hiệu Bermad DN40 | D17: Bộ | CK17: =SUM(E17,L17,S17,Z17,AG17,AN17,AU17,BB17,BI17,BP17,BW17,CD17) -> 0 | CL17: =SUM(F17,M17,T17,AA17,AH17,AO17,AV17,BC17,BJ17,BQ17,BX17,CE17) -> 0 | CM17: =SUM(G17,N17,U17,AB17,AI17,AP17,AW17,BD17,BK17,BR17,BY17,CF17) -> 0 | CN17: =SUM(H17,O17,V17,AC17,AJ17,AQ17,AX17,BE17,BL17,BS17,BZ17,CG17) -> 0 | CO17: =SUM(I17,P17,W17,AD17,AK17,AR17,AY17,BF17,BM17,BT17,CA17,CH17) -> 0 | CP17: =SUM(J17,Q17,X17,AE17,AL17,AS17,AZ17,BG17,BN17,BU17,CB17,CI17) -> 0 | CQ17: =SUM(K17,R17,Y17,AF17,AM17,AT17,BA17,BH17,BO17,BV17,CC17,CJ17) -> 0
B18: ĐH050 | C18: Đồng hồ D50 | D18: Cái | CK18: =SUM(E18,L18,S18,Z18,AG18,AN18,AU18,BB18,BI18,BP18,BW18,CD18) -> 0 | CL18: =SUM(F18,M18,T18,AA18,AH18,AO18,AV18,BC18,BJ18,BQ18,BX18,CE18) -> 0 | CM18: =SUM(G18,N18,U18,AB18,AI18,AP18,AW18,BD18,BK18,BR18,BY18,CF18) -> 0 | CN18: =SUM(H18,O18,V18,AC18,AJ18,AQ18,AX18,BE18,BL18,BS18,BZ18,CG18) -> 0 | CO18: =SUM(I18,P18,W18,AD18,AK18,AR18,AY18,BF18,BM18,BT18,CA18,CH18) -> 0 | CP18: =SUM(J18,Q18,X18,AE18,AL18,AS18,AZ18,BG18,BN18,BU18,CB18,CI18) -> 0 | CQ18: =SUM(K18,R18,Y18,AF18,AM18,AT18,BA18,BH18,BO18,BV18,CC18,CJ18) -> 0
B19: ĐH050(SC) | C19: Đồng hồ D50 (sửa chữa) | D19: Cái | CK19: =SUM(E19,L19,S19,Z19,AG19,AN19,AU19,BB19,BI19,BP19,BW19,CD19) -> 0 | CL19: =SUM(F19,M19,T19,AA19,AH19,AO19,AV19,BC19,BJ19,BQ19,BX19,CE19) -> 0 | CM19: =SUM(G19,N19,U19,AB19,AI19,AP19,AW19,BD19,BK19,BR19,BY19,CF19) -> 0 | CN19: =SUM(H19,O19,V19,AC19,AJ19,AQ19,AX19,BE19,BL19,BS19,BZ19,CG19) -> 0 | CO19: =SUM(I19,P19,W19,AD19,AK19,AR19,AY19,BF19,BM19,BT19,CA19,CH19) -> 0 | CP19: =SUM(J19,Q19,X19,AE19,AL19,AS19,AZ19,BG19,BN19,BU19,CB19,CI19) -> 0 | CQ19: =SUM(K19,R19,Y19,AF19,AM19,AT19,BA19,BH19,BO19,BV19,CC19,CJ19) -> 0
B20: ĐH050-BM | C20: Đồng hồ DN50 hiệu Bermad | D20: Cái | CK20: =SUM(E20,L20,S20,Z20,AG20,AN20,AU20,BB20,BI20,BP20,BW20,CD20) -> 0 | CL20: =SUM(F20,M20,T20,AA20,AH20,AO20,AV20,BC20,BJ20,BQ20,BX20,CE20) -> 0 | CM20: =SUM(G20,N20,U20,AB20,AI20,AP20,AW20,BD20,BK20,BR20,BY20,CF20) -> 0 | CN20: =SUM(H20,O20,V20,AC20,AJ20,AQ20,AX20,BE20,BL20,BS20,BZ20,CG20) -> 0 | CO20: =SUM(I20,P20,W20,AD20,AK20,AR20,AY20,BF20,BM20,BT20,CA20,CH20) -> 0 | CP20: =SUM(J20,Q20,X20,AE20,AL20,AS20,AZ20,BG20,BN20,BU20,CB20,CI20) -> 0 | CQ20: =SUM(K20,R20,Y20,AF20,AM20,AT20,BA20,BH20,BO20,BV20,CC20,CJ20) -> 0
B21: ĐH065 | C21: Đồng hồ D65 | D21: Cái | CK21: =SUM(E21,L21,S21,Z21,AG21,AN21,AU21,BB21,BI21,BP21,BW21,CD21) -> 0 | CL21: =SUM(F21,M21,T21,AA21,AH21,AO21,AV21,BC21,BJ21,BQ21,BX21,CE21) -> 0 | CM21: =SUM(G21,N21,U21,AB21,AI21,AP21,AW21,BD21,BK21,BR21,BY21,CF21) -> 0 | CN21: =SUM(H21,O21,V21,AC21,AJ21,AQ21,AX21,BE21,BL21,BS21,BZ21,CG21) -> 0 | CO21: =SUM(I21,P21,W21,AD21,AK21,AR21,AY21,BF21,BM21,BT21,CA21,CH21) -> 0 | CP21: =SUM(J21,Q21,X21,AE21,AL21,AS21,AZ21,BG21,BN21,BU21,CB21,CI21) -> 0 | CQ21: =SUM(K21,R21,Y21,AF21,AM21,AT21,BA21,BH21,BO21,BV21,CC21,CJ21) -> 0
B22: ĐH065-ĐLL | C22: Đồng hồ đo lưu lượng Turbobar hiệu Bermad DN65 | D22: Bộ | CK22: =SUM(E22,L22,S22,Z22,AG22,AN22,AU22,BB22,BI22,BP22,BW22,CD22) -> 0 | CL22: =SUM(F22,M22,T22,AA22,AH22,AO22,AV22,BC22,BJ22,BQ22,BX22,CE22) -> 0 | CM22: =SUM(G22,N22,U22,AB22,AI22,AP22,AW22,BD22,BK22,BR22,BY22,CF22) -> 0 | CN22: =SUM(H22,O22,V22,AC22,AJ22,AQ22,AX22,BE22,BL22,BS22,BZ22,CG22) -> 0 | CO22: =SUM(I22,P22,W22,AD22,AK22,AR22,AY22,BF22,BM22,BT22,CA22,CH22) -> 0 | CP22: =SUM(J22,Q22,X22,AE22,AL22,AS22,AZ22,BG22,BN22,BU22,CB22,CI22) -> 0 | CQ22: =SUM(K22,R22,Y22,AF22,AM22,AT22,BA22,BH22,BO22,BV22,CC22,CJ22) -> 0
B23: ĐH080 | C23: Đồng hồ D80 | D23: Cái | CK23: =SUM(E23,L23,S23,Z23,AG23,AN23,AU23,BB23,BI23,BP23,BW23,CD23) -> 0 | CL23: =SUM(F23,M23,T23,AA23,AH23,AO23,AV23,BC23,BJ23,BQ23,BX23,CE23) -> 0 | CM23: =SUM(G23,N23,U23,AB23,AI23,AP23,AW23,BD23,BK23,BR23,BY23,CF23) -> 0 | CN23: =SUM(H23,O23,V23,AC23,AJ23,AQ23,AX23,BE23,BL23,BS23,BZ23,CG23) -> 0 | CO23: =SUM(I23,P23,W23,AD23,AK23,AR23,AY23,BF23,BM23,BT23,CA23,CH23) -> 0 | CP23: =SUM(J23,Q23,X23,AE23,AL23,AS23,AZ23,BG23,BN23,BU23,CB23,CI23) -> 0 | CQ23: =SUM(K23,R23,Y23,AF23,AM23,AT23,BA23,BH23,BO23,BV23,CC23,CJ23) -> 0
B24: ĐH100 | C24: Đồng hồ D100 | D24: Cái | CK24: =SUM(E24,L24,S24,Z24,AG24,AN24,AU24,BB24,BI24,BP24,BW24,CD24) -> 0 | CL24: =SUM(F24,M24,T24,AA24,AH24,AO24,AV24,BC24,BJ24,BQ24,BX24,CE24) -> 0 | CM24: =SUM(G24,N24,U24,AB24,AI24,AP24,AW24,BD24,BK24,BR24,BY24,CF24) -> 0 | CN24: =SUM(H24,O24,V24,AC24,AJ24,AQ24,AX24,BE24,BL24,BS24,BZ24,CG24) -> 0 | CO24: =SUM(I24,P24,W24,AD24,AK24,AR24,AY24,BF24,BM24,BT24,CA24,CH24) -> 0 | CP24: =SUM(J24,Q24,X24,AE24,AL24,AS24,AZ24,BG24,BN24,BU24,CB24,CI24) -> 0 | CQ24: =SUM(K24,R24,Y24,AF24,AM24,AT24,BA24,BH24,BO24,BV24,CC24,CJ24) -> 0
B25: ĐH150 | C25: Đồng hồ D150 | D25: Cái | CK25: =SUM(E25,L25,S25,Z25,AG25,AN25,AU25,BB25,BI25,BP25,BW25,CD25) -> 0 | CL25: =SUM(F25,M25,T25,AA25,AH25,AO25,AV25,BC25,BJ25,BQ25,BX25,CE25) -> 0 | CM25: =SUM(G25,N25,U25,AB25,AI25,AP25,AW25,BD25,BK25,BR25,BY25,CF25) -> 0 | CN25: =SUM(H25,O25,V25,AC25,AJ25,AQ25,AX25,BE25,BL25,BS25,BZ25,CG25) -> 0 | CO25: =SUM(I25,P25,W25,AD25,AK25,AR25,AY25,BF25,BM25,BT25,CA25,CH25) -> 0 | CP25: =SUM(J25,Q25,X25,AE25,AL25,AS25,AZ25,BG25,BN25,BU25,CB25,CI25) -> 0 | CQ25: =SUM(K25,R25,Y25,AF25,AM25,AT25,BA25,BH25,BO25,BV25,CC25,CJ25) -> 0
B26: ĐH150-CTOR | C26: Đồng hồ nước DN150 CONTOR-Metcon Qn=150m3/h, cấp B (Pvđ: 4,5-300m3/h) | D26: Cái | CK26: =SUM(E26,L26,S26,Z26,AG26,AN26,AU26,BB26,BI26,BP26,BW26,CD26) -> 0 | CL26: =SUM(F26,M26,T26,AA26,AH26,AO26,AV26,BC26,BJ26,BQ26,BX26,CE26) -> 0 | CM26: =SUM(G26,N26,U26,AB26,AI26,AP26,AW26,BD26,BK26,BR26,BY26,CF26) -> 0 | CN26: =SUM(H26,O26,V26,AC26,AJ26,AQ26,AX26,BE26,BL26,BS26,BZ26,CG26) -> 0 | CO26: =SUM(I26,P26,W26,AD26,AK26,AR26,AY26,BF26,BM26,BT26,CA26,CH26) -> 0 | CP26: =SUM(J26,Q26,X26,AE26,AL26,AS26,AZ26,BG26,BN26,BU26,CB26,CI26) -> 0 | CQ26: =SUM(K26,R26,Y26,AF26,AM26,AT26,BA26,BH26,BO26,BV26,CC26,CJ26) -> 0
B27: ĐH200 | C27: Đồng hồ D200 | D27: Cái | T27: 1 | CK27: =SUM(E27,L27,S27,Z27,AG27,AN27,AU27,BB27,BI27,BP27,BW27,CD27) -> 0 | CL27: =SUM(F27,M27,T27,AA27,AH27,AO27,AV27,BC27,BJ27,BQ27,BX27,CE27) -> 1 | CM27: =SUM(G27,N27,U27,AB27,AI27,AP27,AW27,BD27,BK27,BR27,BY27,CF27) -> 0 | CN27: =SUM(H27,O27,V27,AC27,AJ27,AQ27,AX27,BE27,BL27,BS27,BZ27,CG27) -> 0 | CO27: =SUM(I27,P27,W27,AD27,AK27,AR27,AY27,BF27,BM27,BT27,CA27,CH27) -> 0 | CP27: =SUM(J27,Q27,X27,AE27,AL27,AS27,AZ27,BG27,BN27,BU27,CB27,CI27) -> 0 | CQ27: =SUM(K27,R27,Y27,AF27,AM27,AT27,BA27,BH27,BO27,BV27,CC27,CJ27) -> 0
B28: D25FLD | C28: Đồng hồ D25 Flodis | D28: Cái | F28: 2 | G28: 2 | AH28: 1 | AI28: 1 | CK28: =SUM(E28,L28,S28,Z28,AG28,AN28,AU28,BB28,BI28,BP28,BW28,CD28) -> 0 | CL28: =SUM(F28,M28,T28,AA28,AH28,AO28,AV28,BC28,BJ28,BQ28,BX28,CE28) -> 3 | CM28: =SUM(G28,N28,U28,AB28,AI28,AP28,AW28,BD28,BK28,BR28,BY28,CF28) -> 3 | CN28: =SUM(H28,O28,V28,AC28,AJ28,AQ28,AX28,BE28,BL28,BS28,BZ28,CG28) -> 0 | CO28: =SUM(I28,P28,W28,AD28,AK28,AR28,AY28,BF28,BM28,BT28,CA28,CH28) -> 0 | CP28: =SUM(J28,Q28,X28,AE28,AL28,AS28,AZ28,BG28,BN28,BU28,CB28,CI28) -> 0 | CQ28: =SUM(K28,R28,Y28,AF28,AM28,AT28,BA28,BH28,BO28,BV28,CC28,CJ28) -> 0
B29: D32FLD | C29: Đồng hồ D32 Flodis | D29: Cái | T29: 1 | AO29: 1 | CK29: =SUM(E29,L29,S29,Z29,AG29,AN29,AU29,BB29,BI29,BP29,BW29,CD29) -> 0 | CL29: =SUM(F29,M29,T29,AA29,AH29,AO29,AV29,BC29,BJ29,BQ29,BX29,CE29) -> 2 | CM29: =SUM(G29,N29,U29,AB29,AI29,AP29,AW29,BD29,BK29,BR29,BY29,CF29) -> 0 | CN29: =SUM(H29,O29,V29,AC29,AJ29,AQ29,AX29,BE29,BL29,BS29,BZ29,CG29) -> 0 | CO29: =SUM(I29,P29,W29,AD29,AK29,AR29,AY29,BF29,BM29,BT29,CA29,CH29) -> 0 | CP29: =SUM(J29,Q29,X29,AE29,AL29,AS29,AZ29,BG29,BN29,BU29,CB29,CI29) -> 0 | CQ29: =SUM(K29,R29,Y29,AF29,AM29,AT29,BA29,BH29,BO29,BV29,CC29,CJ29) -> 0
B30: D40FLT | C30: Đồng hồ D40 Flostar | D30: Cái
E31: =SUM(E6:E27) -> 0 | F31: =SUM(F6:F27) -> 132 | G31: =SUM(G6:G27) -> 0 | H31: =SUM(H6:H27) -> 0 | I31: =SUM(I6:I27) -> 0 | J31: =SUM(J6:J27) -> 0 | K31: =SUM(K6:K27) -> 0 | L31: =SUM(L6:L27) -> 0 | ... Z31: =SUM(Z6:Z27) -> 0 | AA31: =SUM(AA6:AA29) -> 230 | AB31: =SUM(AB6:AB27) -> 170 | AC31: =SUM(AC6:AC27) -> 0 | AD31: =SUM(AD6:AD27) -> 0 | AE31: =SUM(AE6:AE27) -> 0 | AF31: =SUM(AF6:AF27) -> 0 | AG31: =SUM(AG6:AG27) -> 0 | AH31: =SUM(AH4:AH29) -> 31 | AI31: =SUM(AI6:AI27) -> 10 | AJ31: =SUM(AJ6:AJ27) -> 0 | AK31: =SUM(AK6:AK27) -> 0 | AL31: =SUM(AL6:AL27) -> 0 | AM31: =SUM(AM6:AM27) -> 0 | AN31: =SUM(AN6:AN27) -> 0 | AO31: =SUM(AO6:AO29) -> 112 | AP31: =SUM(AP6:AP27) -> 91 | AQ31: =SUM(AQ6:AQ27) -> 0 | AR31: =SUM(AR6:AR27) -> 0 | AS31: =SUM(AS6:AS27) -> 0 | AT31: =SUM(AT6:AT27) -> 0 | AU31: =SUM(AU6:AU27) -> 0 | AV31: =SUM(AV6:AV29) -> 110 | AW31: =SUM(AW6:AW27) -> 90 | AX31: =SUM(AX6:AX27) -> 0 | AY31: =SUM(AY6:AY27) -> 0 | AZ31: =SUM(AZ6:AZ27) -> 0 | BA31: =SUM(BA6:BA27) -> 0 | BB31: =SUM(BB6:BB27) -> 0 | BC31: =SUM(BC6:BC29) -> 101 | BD31: =SUM(BD6:BD27) -> 91 | BE31: =SUM(BE6:BE27) -> 0 | BF31: =SUM(BF6:BF27) -> 0 | BG31: =SUM(BG6:BG27) -> 0 | BH31: =SUM(BH6:BH27) -> 0 | BI31: =SUM(BI6:BI27) -> 0 | BJ31: =SUM(BJ6:BJ29) -> 90 | BK31: =SUM(BK6:BK27) -> 0 | BL31: =SUM(BL6:BL27) -> 0 | BM31: =SUM(BM6:BM27) -> 0 | BN31: =SUM(BN6:BN27) -> 0 | BO31: =SUM(BO6:BO27) -> 0 | BP31: =SUM(BP6:BP27) -> 0 | BQ31: =SUM(BQ6:BQ29) -> 0 | BR31: =SUM(BR6:BR27) -> 0 | BS31: =SUM(BS6:BS27) -> 0 | BT31: =SUM(BT6:BT27) -> 0 | BU31: =SUM(BU6:BU27) -> 0 | BV31: =SUM(BV6:BV27) -> 0 | BW31: =SUM(BW6:BW27) -> 0 | BX31: =SUM(BX6:BX29) -> 0 | BY31: =SUM(BY6:BY27) -> 0 | BZ31: =SUM(BZ6:BZ27) -> 0 | CA31: =SUM(CA6:CA27) -> 0 | CB31: =SUM(CB6:CB27) -> 0 | CC31: =SUM(CC6:CC27) -> 0 | CD31: =SUM(CD6:CD27) -> 0 | CE31: =SUM(CE6:CE29) -> 0 | CF31: =SUM(CF6:CF27) -> 0 | CG31: =SUM(CG6:CG27) -> 0 | CH31: =SUM(CH6:CH27) -> 0 | CI31: =SUM(CI6:CI27) -> 0 | CJ31: =SUM(CJ6:CJ27) -> 0 | CK31: =SUM(CK6:CK27) -> 0 | CL31: =SUM(CL6:CL29) -> 1083 | CM31: =SUM(CM6:CM27) -> 563 | CN31: =SUM(CN6:CN27) -> 0 | CO31: =SUM(CO6:CO27) -> 0 | CP31: =SUM(CP6:CP27) -> 0 | CQ31: =SUM(CQ6:CQ27) -> 0

Sheet MS
A1: TỔNG HỢP XUẤT KHO
B3: Mã hàng | C3: Tên hàng | D3: ĐVT | E3: Tháng 1 | L3: Tháng 2 | S3: Tháng 3 | Z3: Tháng 4 | AG3: Tháng 5 | AN3: Tháng 6 | AU3: Tháng 7 | BB3: Tháng 8 | BI3: Tháng 9 | BP3: Tháng 10 | BW3: Tháng 11 | CD3: Tháng 12 | CK3: Cuối kỳ
E4: ĐH quay vòng | F4: Xuất ĐH | G4: ĐH ĐV gửi về | H4: Kiểm tra BH | J4: Kiểm đinh bất thường | L4: ĐH quay vòng | M4: Xuất ĐH | N4: ĐH ĐV gửi về | O4: Kiểm tra BH | Q4: Kiểm đinh bất thường | S4: ĐH quay vòng | T4: Xuất ĐH | U4: ĐH ĐV gửi về | V4: Kiểm tra BH | X4: Kiểm đinh bất thường | Z4: ĐH quay vòng | AA4: Xuất ĐH | AB4: ĐH ĐV gửi về | AC4: Kiểm tra BH | AE4: Kiểm đinh bất thường | AG4: ĐH quay vòng | AH4: Xuất ĐH | AI4: ĐH ĐV gửi về | AJ4: Kiểm tra BH | AL4: Kiểm đinh bất thường | AN4: ĐH quay vòng | AO4: Xuất ĐH | AP4: ĐH ĐV gửi về | AQ4: Kiểm tra BH | AS4: Kiểm đinh bất thường | AU4: ĐH quay vòng | AV4: Xuất ĐH | AW4: ĐH ĐV gửi về | AX4: Kiểm tra BH | AZ4: Kiểm đinh bất thường | BB4: ĐH quay vòng | BC4: Xuất ĐH | BD4: ĐH ĐV gửi về | BE4: Kiểm tra BH | BG4: Kiểm đinh bất thường | BI4: ĐH quay vòng | BJ4: Xuất ĐH | BK4: ĐH ĐV gửi về | BL4: Kiểm tra BH | BN4: Kiểm đinh bất thường | BP4: ĐH quay vòng | BQ4: Xuất ĐH | BR4: ĐH ĐV gửi về | BS4: Kiểm tra BH | BU4: Kiểm đinh bất thường | BW4: ĐH quay vòng | BX4: Xuất ĐH | BY4: ĐH ĐV gửi về | BZ4: Kiểm tra BH | CB4: Kiểm đinh bất thường | CD4: ĐH quay vòng | CE4: Xuất ĐH | CF4: ĐH ĐV gửi về | CG4: Kiểm tra BH | CI4: Kiểm đinh bất thường | CK4: ĐH quay vòng | CL4: Xuất ĐH | CM4: ĐH ĐV gửi về | CN4: Kiểm tra BH | CP4: Kiểm đinh bất thường
A5: Tên kho : 02-Kho Văn phòng Công ty | H5: Đạt | I5: K đạt | J5: Đạt | K5: K đạt | O5: Đạt | P5: K đạt | Q5: Đạt | R5: K đạt | V5: Đạt | W5: K đạt | X5: Đạt | Y5: K đạt | AC5: Đạt | AD5: K đạt | AE5: Đạt | AF5: K đạt | AJ5: Đạt | AK5: K đạt | AL5: Đạt | AM5: K đạt | AQ5: Đạt | AR5: K đạt | AS5: Đạt | AT5: K đạt | AX5: Đạt | AY5: K đạt | AZ5: Đạt | BA5: K đạt | BE5: Đạt | BF5: K đạt | BG5: Đạt | BH5: K đạt | BL5: Đạt | BM5: K đạt | BN5: Đạt | BO5: K đạt | BS5: Đạt | BT5: K đạt | BU5: Đạt | BV5: K đạt | BZ5: Đạt | CA5: K đạt | CB5: Đạt | CC5: K đạt | CG5: Đạt | CH5: K đạt | CI5: Đạt | CJ5: K đạt | CN5: Đạt | CO5: K đạt | CP5: Đạt | CQ5: K đạt
B6: ĐH015 | C6: Đồng hồ D15 | D6: Cái | F6: 10 | T6: 10 | AA6: 90 | AH6: 20 | AO6: 10 | AV6: 10 | CK6: =SUM(E6,L6,S6,Z6,AG6,AN6,AU6,BB6,BI6,BP6,BW6,CD6) -> 0 | CL6: =SUM(F6,M6,T6,AA6,AH6,AO6,AV6,BC6,BJ6,BQ6,BX6,CE6) -> 150 | CM6: =SUM(G6,N6,U6,AB6,AI6,AP6,AW6,BD6,BK6,BR6,BY6,CF6) -> 0 | CN6: =SUM(H6,O6,V6,AC6,AJ6,AQ6,AX6,BE6,BL6,BS6,BZ6,CG6) -> 0 | CO6: =SUM(I6,P6,W6,AD6,AK6,AR6,AY6,BF6,BM6,BT6,CA6,CH6) -> 0 | CP6: =SUM(J6,Q6,X6,AE6,AL6,AS6,AZ6,BG6,BN6,BU6,CB6,CI6) -> 0 | CQ6: =SUM(K6,R6,Y6,AF6,AM6,AT6,BA6,BH6,BO6,BV6,CC6,CJ6) -> 0
B7: ĐH015(SC) | C7: Đồng hồ sửa chữa 015 | D7: Cái | F7: 140 | G7: =70+60+9 -> 139 | M7: 140 | T7: 140 | U7: 140 | AA7: 70 | AB7: 210 | AH7: 70 | AO7: 90 | AP7: 84 | AV7: 100 | AW7: 106 | BC7: 100 | BD7: 90 | BJ7: 100 | CK7: =SUM(E7,L7,S7,Z7,AG7,AN7,AU7,BB7,BI7,BP7,BW7,CD7) -> 0 | CL7: =SUM(F7,M7,T7,AA7,AH7,AO7,AV7,BC7,BJ7,BQ7,BX7,CE7) -> 950 | CM7: =SUM(G7,N7,U7,AB7,AI7,AP7,AW7,BD7,BK7,BR7,BY7,CF7) -> 769 | CN7: =SUM(H7,O7,V7,AC7,AJ7,AQ7,AX7,BE7,BL7,BS7,BZ7,CG7) -> 0 | CO7: =SUM(I7,P7,W7,AD7,AK7,AR7,AY7,BF7,BM7,BT7,CA7,CH7) -> 0 | CP7: =SUM(J7,Q7,X7,AE7,AL7,AS7,AZ7,BG7,BN7,BU7,CB7,CI7) -> 0 | CQ7: =SUM(K7,R7,Y7,AF7,AM7,AT7,BA7,BH7,BO7,BV7,CC7,CJ7) -> 0
B8: ĐH015(SC) | C8: Đồng hồ sửa chữa 015 đơn vị | D8: Cái | CK8: =SUM(E8,L8,S8,Z8,AG8,AN8,AU8,BB8,BI8,BP8,BW8,CD8) -> 0 | CL8: =SUM(F8,M8,T8,AA8,AH8,AO8,AV8,BC8,BJ8,BQ8,BX8,CE8) -> 0 | CM8: =SUM(G8,N8,U8,AB8,AI8,AP8,AW8,BD8,BK8,BR8,BY8,CF8) -> 0 | CN8: =SUM(H8,O8,V8,AC8,AJ8,AQ8,AX8,BE8,BL8,BS8,BZ8,CG8) -> 0 | CO8: =SUM(I8,P8,W8,AD8,AK8,AR8,AY8,BF8,BM8,BT8,CA8,CH8) -> 0 | CP8: =SUM(J8,Q8,X8,AE8,AL8,AS8,AZ8,BG8,BN8,BU8,CB8,CI8) -> 0 | CQ8: =SUM(K8,R8,Y8,AF8,AM8,AT8,BA8,BH8,BO8,BV8,CC8,CJ8) -> 0
B9: ĐH015-TAC | C9: Đồng hồ Thái Aichi MAM-15 ( không kèm rắc co) | D9: Cái | CK9: =SUM(E9,L9,S9,Z9,AG9,AN9,AU9,BB9,BI9,BP9,BW9,CD9) -> 0 | CL9: =SUM(F9,M9,T9,AA9,AH9,AO9,AV9,BC9,BJ9,BQ9,BX9,CE9) -> 0 | CM9: =SUM(G9,N9,U9,AB9,AI9,AP9,AW9,BD9,BK9,BR9,BY9,CF9) -> 0 | CN9: =SUM(H9,O9,V9,AC9,AJ9,AQ9,AX9,BE9,BL9,BS9,BZ9,CG9) -> 0 | CO9: =SUM(I9,P9,W9,AD9,AK9,AR9,AY9,BF9,BM9,BT9,CA9,CH9) -> 0 | CP9: =SUM(J9,Q9,X9,AE9,AL9,AS9,AZ9,BG9,BN9,BU9,CB9,CI9) -> 0 | CQ9: =SUM(K9,R9,Y9,AF9,AM9,AT9,BA9,BH9,BO9,BV9,CC9,CJ9) -> 0
B10: ĐH020 | C10: Đồng hồ D20 | D10: Cái | CK10: =SUM(E10,L10,S10,Z10,AG10,AN10,AU10,BB10,BI10,BP10,BW10,CD10) -> 0 | CL10: =SUM(F10,M10,T10,AA10,AH10,AO10,AV10,BC10,BJ10,BQ10,BX10,CE10) -> 0 | CM10: =SUM(G10,N10,U10,AB10,AI10,AP10,AW10,BD10,BK10,BR10,BY10,CF10) -> 0 | CN10: =SUM(H10,O10,V10,AC10,AJ10,AQ10,AX10,BE10,BL10,BS10,BZ10,CG10) -> 0 | CO10: =SUM(I10,P10,W10,AD10,AK10,AR10,AY10,BF10,BM10,BT10,CA10,CH10) -> 0 | CP10: =SUM(J10,Q10,X10,AE10,AL10,AS10,AZ10,BG10,BN10,BU10,CB10,CI10) -> 0 | CQ10: =SUM(K10,R10,Y10,AF10,AM10,AT10,BA10,BH10,BO10,BV10,CC10,CJ10) -> 0
B11: ĐH025 | C11: Đồng hồ D25 | D11: Cái | CK11: =SUM(E11,L11,S11,Z11,AG11,AN11,AU11,BB11,BI11,BP11,BW11,CD11) -> 0 | CL11: =SUM(F11,M11,T11,AA11,AH11,AO11,AV11,BC11,BJ11,BQ11,BX11,CE11) -> 0 | CM11: =SUM(G11,N11,U11,AB11,AI11,AP11,AW11,BD11,BK11,BR11,BY11,CF11) -> 0 | CN11: =SUM(H11,O11,V11,AC11,AJ11,AQ11,AX11,BE11,BL11,BS11,BZ11,CG11) -> 0 | CO11: =SUM(I11,P11,W11,AD11,AK11,AR11,AY11,BF11,BM11,BT11,CA11,CH11) -> 0 | CP11: =SUM(J11,Q11,X11,AE11,AL11,AS11,AZ11,BG11,BN11,BU11,CB11,CI11) -> 0 | CQ11: =SUM(K11,R11,Y11,AF11,AM11,AT11,BA11,BH11,BO11,BV11,CC11,CJ11) -> 0
B12: ĐH025(SC) | C12: Đồng hồ D25 (sửa chữa) | D12: Cái | CK12: =SUM(E12,L12,S12,Z12,AG12,AN12,AU12,BB12,BI12,BP12,BW12,CD12) -> 0 | CL12: =SUM(F12,M12,T12,AA12,AH12,AO12,AV12,BC12,BJ12,BQ12,BX12,CE12) -> 0 | CM12: =SUM(G12,N12,U12,AB12,AI12,AP12,AW12,BD12,BK12,BR12,BY12,CF12) -> 0 | CN12: =SUM(H12,O12,V12,AC12,AJ12,AQ12,AX12,BE12,BL12,BS12,BZ12,CG12) -> 0 | CO12: =SUM(I12,P12,W12,AD12,AK12,AR12,AY12,BF12,BM12,BT12,CA12,CH12) -> 0 | CP12: =SUM(J12,Q12,X12,AE12,AL12,AS12,AZ12,BG12,BN12,BU12,CB12,CI12) -> 0 | CQ12: =SUM(K12,R12,Y12,AF12,AM12,AT12,BA12,BH12,BO12,BV12,CC12,CJ12) -> 0
B13: ĐH032 | C13: Đồng hồ D32 | D13: Cái | CK13: =SUM(E13,L13,S13,Z13,AG13,AN13,AU13,BB13,BI13,BP13,BW13,CD13) -> 0 | CL13: =SUM(F13,M13,T13,AA13,AH13,AO13,AV13,BC13,BJ13,BQ13,BX13,CE13) -> 0 | CM13: =SUM(G13,N13,U13,AB13,AI13,AP13,AW13,BD13,BK13,BR13,BY13,CF13) -> 0 | CN13: =SUM(H13,O13,V13,AC13,AJ13,AQ13,AX13,BE13,BL13,BS13,BZ13,CG13) -> 0 | CO13: =SUM(I13,P13,W13,AD13,AK13,AR13,AY13,BF13,BM13,BT13,CA13,CH13) -> 0 | CP13: =SUM(J13,Q13,X13,AE13,AL13,AS13,AZ13,BG13,BN13,BU13,CB13,CI13) -> 0 | CQ13: =SUM(K13,R13,Y13,AF13,AM13,AT13,BA13,BH13,BO13,BV13,CC13,CJ13) -> 0
B14: ĐH032(SC) | C14: Đồng hồ D32 (sửa chữa) | D14: Cái | CK14: =SUM(E14,L14,S14,Z14,AG14,AN14,AU14,BB14,BI14,BP14,BW14,CD14) -> 0 | CL14: =SUM(F14,M14,T14,AA14,AH14,AO14,AV14,BC14,BJ14,BQ14,BX14,CE14) -> 0 | CM14: =SUM(G14,N14,U14,AB14,AI14,AP14,AW14,BD14,BK14,BR14,BY14,CF14) -> 0 | CN14: =SUM(H14,O14,V14,AC14,AJ14,AQ14,AX14,BE14,BL14,BS14,BZ14,CG14) -> 0 | CO14: =SUM(I14,P14,W14,AD14,AK14,AR14,AY14,BF14,BM14,BT14,CA14,CH14) -> 0 | CP14: =SUM(J14,Q14,X14,AE14,AL14,AS14,AZ14,BG14,BN14,BU14,CB14,CI14) -> 0 | CQ14: =SUM(K14,R14,Y14,AF14,AM14,AT14,BA14,BH14,BO14,BV14,CC14,CJ14) -> 0
B15: ĐH040 | C15: Đồng hồ D40 | D15: Cái | F15: 1 | U15: 1 | AA15: 2 | AO15: 1 | AP15: 1 | BD15: 2 | CK15: =SUM(E15,L15,S15,Z15,AG15,AN15,AU15,BB15,BI15,BP15,BW15,CD15) -> 0 | CL15: =SUM(F15,M15,T15,AA15,AH15,AO15,AV15,BC15,BJ15,BQ15,BX15,CE15) -> 4 | CM15: =SUM(G15,N15,U15,AB15,AI15,AP15,AW15,BD15,BK15,BR15,BY15,CF15) -> 4 | CN15: =SUM(H15,O15,V15,AC15,AJ15,AQ15,AX15,BE15,BL15,BS15,BZ15,CG15) -> 0 | CO15: =SUM(I15,P15,W15,AD15,AK15,AR15,AY15,BF15,BM15,BT15,CA15,CH15) -> 0 | CP15: =SUM(J15,Q15,X15,AE15,AL15,AS15,AZ15,BG15,BN15,BU15,CB15,CI15) -> 0 | CQ15: =SUM(K15,R15,Y15,AF15,AM15,AT15,BA15,BH15,BO15,BV15,CC15,CJ15) -> 0
B16: ĐH040(SC) | C16: Đồng hồ D40 (sửa chữa) | D16: Cái | F16: 1 | CK16: =SUM(E16,L16,S16,Z16,AG16,AN16,AU16,BB16,BI16,BP16,BW16,CD16) -> 0 | CL16: =SUM(F16,M16,T16,AA16,AH16,AO16,AV16,BC16,BJ16,BQ16,BX16,CE16) -> 1 | CM16: =SUM(G16,N16,U16,AB16,AI16,AP16,AW16,BD16,BK16,BR16,BY16,CF16) -> 0 | CN16: =SUM(H16,O16,V16,AC16,AJ16,AQ16,AX16,BE16,BL16,BS16,BZ16,CG16) -> 0 | CO16: =SUM(I16,P16,W16,AD16,AK16,AR16,AY16,BF16,BM16,BT16,CA16,CH16) -> 0 | CP16: =SUM(J16,Q16,X16,AE16,AL16,AS16,AZ16,BG16,BN16,BU16,CB16,CI16) -> 0 | CQ16: =SUM(K16,R16,Y16,AF16,AM16,AT16,BA16,BH16,BO16,BV16,CC16,CJ16) -> 0
B17: ĐH040-ĐLL | C17: Đồng hồ đo lưu lượng Turbobar hiệu Bermad DN40 | D17: Bộ | CK17: =SUM(E17,L17,S17,Z17,AG17,AN17,AU17,BB17,BI17,BP17,BW17,CD17) -> 0 | CL17: =SUM(F17,M17,T17,AA17,AH17,AO17,AV17,BC17,BJ17,BQ17,BX17,CE17) -> 0 | CM17: =SUM(G17,N17,U17,AB17,AI17,AP17,AW17,BD17,BK17,BR17,BY17,CF17) -> 0 | CN17: =SUM(H17,O17,V17,AC17,AJ17,AQ17,AX17,BE17,BL17,BS17,BZ17,CG17) -> 0 | CO17: =SUM(I17,P17,W17,AD17,AK17,AR17,AY17,BF17,BM17,BT17,CA17,CH17) -> 0 | CP17: =SUM(J17,Q17,X17,AE17,AL17,AS17,AZ17,BG17,BN17,BU17,CB17,CI17) -> 0 | CQ17: =SUM(K17,R17,Y17,AF17,AM17,AT17,BA17,BH17,BO17,BV17,CC17,CJ17) -> 0
B18: ĐH050 | C18: Đồng hồ D50 | D18: Cái | AA18: 1 | AB18: 1 | CK18: =SUM(E18,L18,S18,Z18,AG18,AN18,AU18,BB18,BI18,BP18,BW18,CD18) -> 0 | CL18: =SUM(F18,M18,T18,AA18,AH18,AO18,AV18,BC18,BJ18,BQ18,BX18,CE18) -> 1 | CM18: =SUM(G18,N18,U18,AB18,AI18,AP18,AW18,BD18,BK18,BR18,BY18,CF18) -> 1 | CN18: =SUM(H18,O18,V18,AC18,AJ18,AQ18,AX18,BE18,BL18,BS18,BZ18,CG18) -> 0 | CO18: =SUM(I18,P18,W18,AD18,AK18,AR18,AY18,BF18,BM18,BT18,CA18,CH18) -> 0 | CP18: =SUM(J18,Q18,X18,AE18,AL18,AS18,AZ18,BG18,BN18,BU18,CB18,CI18) -> 0 | CQ18: =SUM(K18,R18,Y18,AF18,AM18,AT18,BA18,BH18,BO18,BV18,CC18,CJ18) -> 0
B19: ĐH050(SC) | C19: Đồng hồ D50 (sửa chữa) | D19: Cái | CK19: =SUM(E19,L19,S19,Z19,AG19,AN19,AU19,BB19,BI19,BP19,BW19,CD19) -> 0 | CL19: =SUM(F19,M19,T19,AA19,AH19,AO19,AV19,BC19,BJ19,BQ19,BX19,CE19) -> 0 | CM19: =SUM(G19,N19,U19,AB19,AI19,AP19,AW19,BD19,BK19,BR19,BY19,CF19) -> 0 | CN19: =SUM(H19,O19,V19,AC19,AJ19,AQ19,AX19,BE19,BL19,BS19,BZ19,CG19) -> 0 | CO19: =SUM(I19,P19,W19,AD19,AK19,AR19,AY19,BF19,BM19,BT19,CA19,CH19) -> 0 | CP19: =SUM(J19,Q19,X19,AE19,AL19,AS19,AZ19,BG19,BN19,BU19,CB19,CI19) -> 0 | CQ19: =SUM(K19,R19,Y19,AF19,AM19,AT19,BA19,BH19,BO19,BV19,CC19,CJ19) -> 0
B20: ĐH050-BM | C20: Đồng hồ DN50 hiệu Bermad | D20: Cái | CK20: =SUM(E20,L20,S20,Z20,AG20,AN20,AU20,BB20,BI20,BP20,BW20,CD20) -> 0 | CL20: =SUM(F20,M20,T20,AA20,AH20,AO20,AV20,BC20,BJ20,BQ20,BX20,CE20) -> 0 | CM20: =SUM(G20,N20,U20,AB20,AI20,AP20,AW20,BD20,BK20,BR20,BY20,CF20) -> 0 | CN20: =SUM(H20,O20,V20,AC20,AJ20,AQ20,AX20,BE20,BL20,BS20,BZ20,CG20) -> 0 | CO20: =SUM(I20,P20,W20,AD20,AK20,AR20,AY20,BF20,BM20,BT20,CA20,CH20) -> 0 | CP20: =SUM(J20,Q20,X20,AE20,AL20,AS20,AZ20,BG20,BN20,BU20,CB20,CI20) -> 0 | CQ20: =SUM(K20,R20,Y20,AF20,AM20,AT20,BA20,BH20,BO20,BV20,CC20,CJ20) -> 0
B21: ĐH065 | C21: Đồng hồ D65 | D21: Cái | CK21: =SUM(E21,L21,S21,Z21,AG21,AN21,AU21,BB21,BI21,BP21,BW21,CD21) -> 0 | CL21: =SUM(F21,M21,T21,AA21,AH21,AO21,AV21,BC21,BJ21,BQ21,BX21,CE21) -> 0 | CM21: =SUM(G21,N21,U21,AB21,AI21,AP21,AW21,BD21,BK21,BR21,BY21,CF21) -> 0 | CN21: =SUM(H21,O21,V21,AC21,AJ21,AQ21,AX21,BE21,BL21,BS21,BZ21,CG21) -> 0 | CO21: =SUM(I21,P21,W21,AD21,AK21,AR21,AY21,BF21,BM21,BT21,CA21,CH21) -> 0 | CP21: =SUM(J21,Q21,X21,AE21,AL21,AS21,AZ21,BG21,BN21,BU21,CB21,CI21) -> 0 | CQ21: =SUM(K21,R21,Y21,AF21,AM21,AT21,BA21,BH21,BO21,BV21,CC21,CJ21) -> 0
B22: ĐH065-ĐLL | C22: Đồng hồ đo lưu lượng Turbobar hiệu Bermad DN65 | D22: Bộ | CK22: =SUM(E22,L22,S22,Z22,AG22,AN22,AU22,BB22,BI22,BP22,BW22,CD22) -> 0 | CL22: =SUM(F22,M22,T22,AA22,AH22,AO22,AV22,BC22,BJ22,BQ22,BX22,CE22) -> 0 | CM22: =SUM(G22,N22,U22,AB22,AI22,AP22,AW22,BD22,BK22,BR22,BY22,CF22) -> 0 | CN22: =SUM(H22,O22,V22,AC22,AJ22,AQ22,AX22,BE22,BL22,BS22,BZ22,CG22) -> 0 | CO22: =SUM(I22,P22,W22,AD22,AK22,AR22,AY22,BF22,BM22,BT22,CA22,CH22) -> 0 | CP22: =SUM(J22,Q22,X22,AE22,AL22,AS22,AZ22,BG22,BN22,BU22,CB22,CI22) -> 0 | CQ22: =SUM(K22,R22,Y22,AF22,AM22,AT22,BA22,BH22,BO22,BV22,CC22,CJ22) -> 0
B23: ĐH080 | C23: Đồng hồ D80 | D23: Cái | CK23: =SUM(E23,L23,S23,Z23,AG23,AN23,AU23,BB23,BI23,BP23,BW23,CD23) -> 0 | CL23: =SUM(F23,M23,T23,AA23,AH23,AO23,AV23,BC23,BJ23,BQ23,BX23,CE23) -> 0 | CM23: =SUM(G23,N23,U23,AB23,AI23,AP23,AW23,BD23,BK23,BR23,BY23,CF23) -> 0 | CN23: =SUM(H23,O23,V23,AC23,AJ23,AQ23,AX23,BE23,BL23,BS23,BZ23,CG23) -> 0 | CO23: =SUM(I23,P23,W23,AD23,AK23,AR23,AY23,BF23,BM23,BT23,CA23,CH23) -> 0 | CP23: =SUM(J23,Q23,X23,AE23,AL23,AS23,AZ23,BG23,BN23,BU23,CB23,CI23) -> 0 | CQ23: =SUM(K23,R23,Y23,AF23,AM23,AT23,BA23,BH23,BO23,BV23,CC23,CJ23) -> 0
B24: ĐH100 | C24: Đồng hồ D100 | D24: Cái | F24: 1 | CK24: =SUM(E24,L24,S24,Z24,AG24,AN24,AU24,BB24,BI24,BP24,BW24,CD24) -> 0 | CL24: =SUM(F24,M24,T24,AA24,AH24,AO24,AV24,BC24,BJ24,BQ24,BX24,CE24) -> 1 | CM24: =SUM(G24,N24,U24,AB24,AI24,AP24,AW24,BD24,BK24,BR24,BY24,CF24) -> 0 | CN24: =SUM(H24,O24,V24,AC24,AJ24,AQ24,AX24,BE24,BL24,BS24,BZ24,CG24) -> 0 | CO24: =SUM(I24,P24,W24,AD24,AK24,AR24,AY24,BF24,BM24,BT24,CA24,CH24) -> 0 | CP24: =SUM(J24,Q24,X24,AE24,AL24,AS24,AZ24,BG24,BN24,BU24,CB24,CI24) -> 0 | CQ24: =SUM(K24,R24,Y24,AF24,AM24,AT24,BA24,BH24,BO24,BV24,CC24,CJ24) -> 0
B25: ĐH150 | C25: Đồng hồ D150 | D25: Cái | CK25: =SUM(E25,L25,S25,Z25,AG25,AN25,AU25,BB25,BI25,BP25,BW25,CD25) -> 0 | CL25: =SUM(F25,M25,T25,AA25,AH25,AO25,AV25,BC25,BJ25,BQ25,BX25,CE25) -> 0 | CM25: =SUM(G25,N25,U25,AB25,AI25,AP25,AW25,BD25,BK25,BR25,BY25,CF25) -> 0 | CN25: =SUM(H25,O25,V25,AC25,AJ25,AQ25,AX25,BE25,BL25,BS25,BZ25,CG25) -> 0 | CO25: =SUM(I25,P25,W25,AD25,AK25,AR25,AY25,BF25,BM25,BT25,CA25,CH25) -> 0 | CP25: =SUM(J25,Q25,X25,AE25,AL25,AS25,AZ25,BG25,BN25,BU25,CB25,CI25) -> 0 | CQ25: =SUM(K25,R25,Y25,AF25,AM25,AT25,BA25,BH25,BO25,BV25,CC25,CJ25) -> 0
B26: ĐH150-CTOR | C26: Đồng hồ nước DN150 CONTOR-Metcon Qn=150m3/h, cấp B (Pvđ: 4,5-300m3/h) | D26: Cái | CK26: =SUM(E26,L26,S26,Z26,AG26,AN26,AU26,BB26,BI26,BP26,BW26,CD26) -> 0 | CL26: =SUM(F26,M26,T26,AA26,AH26,AO26,AV26,BC26,BJ26,BQ26,BX26,CE26) -> 0 | CM26: =SUM(G26,N26,U26,AB26,AI26,AP26,AW26,BD26,BK26,BR26,BY26,CF26) -> 0 | CN26: =SUM(H26,O26,V26,AC26,AJ26,AQ26,AX26,BE26,BL26,BS26,BZ26,CG26) -> 0 | CO26: =SUM(I26,P26,W26,AD26,AK26,AR26,AY26,BF26,BM26,BT26,CA26,CH26) -> 0 | CP26: =SUM(J26,Q26,X26,AE26,AL26,AS26,AZ26,BG26,BN26,BU26,CB26,CI26) -> 0 | CQ26: =SUM(K26,R26,Y26,AF26,AM26,AT26,BA26,BH26,BO26,BV26,CC26,CJ26) -> 0
B27: ĐH200 | C27: Đồng hồ D200 | D27: Cái | F27: 1 | CK27: =SUM(E27,L27,S27,Z27,AG27,AN27,AU27,BB27,BI27,BP27,BW27,CD27) -> 0 | CL27: =SUM(F27,M27,T27,AA27,AH27,AO27,AV27,BC27,BJ27,BQ27,BX27,CE27) -> 1 | CM27: =SUM(G27,N27,U27,AB27,AI27,AP27,AW27,BD27,BK27,BR27,BY27,CF27) -> 0 | CN27: =SUM(H27,O27,V27,AC27,AJ27,AQ27,AX27,BE27,BL27,BS27,BZ27,CG27) -> 0 | CO27: =SUM(I27,P27,W27,AD27,AK27,AR27,AY27,BF27,BM27,BT27,CA27,CH27) -> 0 | CP27: =SUM(J27,Q27,X27,AE27,AL27,AS27,AZ27,BG27,BN27,BU27,CB27,CI27) -> 0 | CQ27: =SUM(K27,R27,Y27,AF27,AM27,AT27,BA27,BH27,BO27,BV27,CC27,CJ27) -> 0
